ERROR 2024-08-17 14:22:22,087 views Catch Key...: question_data_code_3
ERROR 2024-08-17 14:22:22,129 views -----Data From Cache----
ERROR 2024-08-17 14:22:22,153 views -----Data From Database----
ERROR 2024-08-17 14:23:18,440 views Catch Key...: question_data_code_3
ERROR 2024-08-17 14:23:18,484 views -----Data From Cache----
ERROR 2024-08-17 14:26:19,489 views Catch Key...: question_data_code_3
ERROR 2024-08-17 14:26:19,700 views -----Data From Cache----
ERROR 2024-08-17 18:06:30,043 log Internal Server Error: /api/clear-log/
ERROR 2024-08-17 18:06:30,045 basehttp "GET /api/clear-log/ HTTP/1.1" 500 159
ERROR 2024-08-17 18:34:45,282 log Internal Server Error: /api/clear-log/
ERROR 2024-08-17 18:34:45,289 basehttp "GET /api/clear-log/ HTTP/1.1" 500 159
ERROR 2024-08-17 18:34:57,835 log Internal Server Error: /api/clear-log/
ERROR 2024-08-17 18:34:57,836 basehttp "GET /api/clear-log/ HTTP/1.1" 500 159
ERROR 2024-08-19 10:50:06,449 log Internal Server Error: /api/login-view/
Traceback (most recent call last):
  File "C:\Users\LENOVO\AppData\Roaming\Python\Python312\site-packages\django\core\handlers\exception.py", line 55, in inner
    response = get_response(request)
               ^^^^^^^^^^^^^^^^^^^^^
  File "C:\Users\LENOVO\AppData\Roaming\Python\Python312\site-packages\django\core\handlers\base.py", line 197, in _get_response
    response = wrapped_callback(request, *callback_args, **callback_kwargs)
               ^^^^^^^^^^^^^^^^^^^^^^^^^^^^^^^^^^^^^^^^^^^^^^^^^^^^^^^^^^^^
  File "C:\Users\LENOVO\AppData\Roaming\Python\Python312\site-packages\django\views\decorators\csrf.py", line 65, in _view_wrapper
    return view_func(request, *args, **kwargs)
           ^^^^^^^^^^^^^^^^^^^^^^^^^^^^^^^^^^^
  File "C:\Users\LENOVO\AppData\Roaming\Python\Python312\site-packages\django\views\generic\base.py", line 104, in view
    return self.dispatch(request, *args, **kwargs)
           ^^^^^^^^^^^^^^^^^^^^^^^^^^^^^^^^^^^^^^^
  File "C:\Users\LENOVO\AppData\Roaming\Python\Python312\site-packages\rest_framework\views.py", line 509, in dispatch
    response = self.handle_exception(exc)
               ^^^^^^^^^^^^^^^^^^^^^^^^^^
  File "C:\Users\LENOVO\AppData\Roaming\Python\Python312\site-packages\rest_framework\views.py", line 469, in handle_exception
    self.raise_uncaught_exception(exc)
  File "C:\Users\LENOVO\AppData\Roaming\Python\Python312\site-packages\rest_framework\views.py", line 480, in raise_uncaught_exception
    raise exc
  File "C:\Users\LENOVO\AppData\Roaming\Python\Python312\site-packages\rest_framework\views.py", line 506, in dispatch
    response = handler(request, *args, **kwargs)
               ^^^^^^^^^^^^^^^^^^^^^^^^^^^^^^^^^
  File "C:\Users\LENOVO\AppData\Roaming\Python\Python312\site-packages\rest_framework\decorators.py", line 50, in handler
    return func(*args, **kwargs)
           ^^^^^^^^^^^^^^^^^^^^^
  File "D:\V_Project\LMS-New\backend\app\views.py", line 5784, in login_view
    user = authenticate(username=username, password=password)
           ^^^^^^^^^^^^
NameError: name 'authenticate' is not defined
ERROR 2024-08-19 10:50:06,556 basehttp "POST /api/login-view/ HTTP/1.1" 500 100024
ERROR 2024-08-19 13:32:24,557 log Internal Server Error: /api/logout/
Traceback (most recent call last):
  File "C:\Users\LENOVO\AppData\Roaming\Python\Python312\site-packages\django\core\handlers\exception.py", line 55, in inner
    response = get_response(request)
               ^^^^^^^^^^^^^^^^^^^^^
  File "C:\Users\LENOVO\AppData\Roaming\Python\Python312\site-packages\django\core\handlers\base.py", line 197, in _get_response
    response = wrapped_callback(request, *callback_args, **callback_kwargs)
               ^^^^^^^^^^^^^^^^^^^^^^^^^^^^^^^^^^^^^^^^^^^^^^^^^^^^^^^^^^^^
  File "C:\Users\LENOVO\AppData\Roaming\Python\Python312\site-packages\django\views\decorators\csrf.py", line 65, in _view_wrapper
    return view_func(request, *args, **kwargs)
           ^^^^^^^^^^^^^^^^^^^^^^^^^^^^^^^^^^^
  File "D:\V_Project\LMS-New\backend\app\views.py", line 5823, in logout_view
    print('Session cleared: ', request.session.exists())
                               ^^^^^^^^^^^^^^^^^^^^^^^^
TypeError: SessionStore.exists() missing 1 required positional argument: 'session_key'
ERROR 2024-08-19 13:32:25,403 basehttp "POST /api/logout/ HTTP/1.1" 500 70171
ERROR 2024-08-19 14:54:45,222 log Internal Server Error: /api/question/import_excel/
Traceback (most recent call last):
  File "C:\Users\LENOVO\AppData\Roaming\Python\Python312\site-packages\django\core\handlers\exception.py", line 55, in inner
    response = get_response(request)
               ^^^^^^^^^^^^^^^^^^^^^
  File "C:\Users\LENOVO\AppData\Roaming\Python\Python312\site-packages\django\core\handlers\base.py", line 197, in _get_response
    response = wrapped_callback(request, *callback_args, **callback_kwargs)
               ^^^^^^^^^^^^^^^^^^^^^^^^^^^^^^^^^^^^^^^^^^^^^^^^^^^^^^^^^^^^
  File "C:\Users\LENOVO\AppData\Roaming\Python\Python312\site-packages\django\views\decorators\csrf.py", line 65, in _view_wrapper
    return view_func(request, *args, **kwargs)
           ^^^^^^^^^^^^^^^^^^^^^^^^^^^^^^^^^^^
  File "C:\Users\LENOVO\AppData\Roaming\Python\Python312\site-packages\django\views\generic\base.py", line 104, in view
    return self.dispatch(request, *args, **kwargs)
           ^^^^^^^^^^^^^^^^^^^^^^^^^^^^^^^^^^^^^^^
  File "C:\Users\LENOVO\AppData\Roaming\Python\Python312\site-packages\rest_framework\views.py", line 509, in dispatch
    response = self.handle_exception(exc)
               ^^^^^^^^^^^^^^^^^^^^^^^^^^
  File "C:\Users\LENOVO\AppData\Roaming\Python\Python312\site-packages\rest_framework\views.py", line 469, in handle_exception
    self.raise_uncaught_exception(exc)
  File "C:\Users\LENOVO\AppData\Roaming\Python\Python312\site-packages\rest_framework\views.py", line 480, in raise_uncaught_exception
    raise exc
  File "C:\Users\LENOVO\AppData\Roaming\Python\Python312\site-packages\rest_framework\views.py", line 506, in dispatch
    response = handler(request, *args, **kwargs)
               ^^^^^^^^^^^^^^^^^^^^^^^^^^^^^^^^^
  File "D:\V_Project\LMS-New\backend\app\views.py", line 2541, in post
    for idx, error in enumerate(serializer.errors.get('non_field_errors', [])):
                                ^^^^^^^^^^^^^^^^^^^^^
AttributeError: 'ReturnList' object has no attribute 'get'
ERROR 2024-08-19 14:54:46,336 basehttp "POST /api/question/import_excel/ HTTP/1.1" 500 120090
ERROR 2024-08-19 14:58:29,881 log Internal Server Error: /api/question/import_excel/
Traceback (most recent call last):
  File "C:\Users\LENOVO\AppData\Roaming\Python\Python312\site-packages\django\core\handlers\exception.py", line 55, in inner
    response = get_response(request)
               ^^^^^^^^^^^^^^^^^^^^^
  File "C:\Users\LENOVO\AppData\Roaming\Python\Python312\site-packages\django\core\handlers\base.py", line 197, in _get_response
    response = wrapped_callback(request, *callback_args, **callback_kwargs)
               ^^^^^^^^^^^^^^^^^^^^^^^^^^^^^^^^^^^^^^^^^^^^^^^^^^^^^^^^^^^^
  File "C:\Users\LENOVO\AppData\Roaming\Python\Python312\site-packages\django\views\decorators\csrf.py", line 65, in _view_wrapper
    return view_func(request, *args, **kwargs)
           ^^^^^^^^^^^^^^^^^^^^^^^^^^^^^^^^^^^
  File "C:\Users\LENOVO\AppData\Roaming\Python\Python312\site-packages\django\views\generic\base.py", line 104, in view
    return self.dispatch(request, *args, **kwargs)
           ^^^^^^^^^^^^^^^^^^^^^^^^^^^^^^^^^^^^^^^
  File "C:\Users\LENOVO\AppData\Roaming\Python\Python312\site-packages\rest_framework\views.py", line 509, in dispatch
    response = self.handle_exception(exc)
               ^^^^^^^^^^^^^^^^^^^^^^^^^^
  File "C:\Users\LENOVO\AppData\Roaming\Python\Python312\site-packages\rest_framework\views.py", line 469, in handle_exception
    self.raise_uncaught_exception(exc)
  File "C:\Users\LENOVO\AppData\Roaming\Python\Python312\site-packages\rest_framework\views.py", line 480, in raise_uncaught_exception
    raise exc
  File "C:\Users\LENOVO\AppData\Roaming\Python\Python312\site-packages\rest_framework\views.py", line 506, in dispatch
    response = handler(request, *args, **kwargs)
               ^^^^^^^^^^^^^^^^^^^^^^^^^^^^^^^^^
  File "D:\V_Project\LMS-New\backend\app\views.py", line 2541, in post
    for idx, error in enumerate(serializer.errors.get('non_field_errors', [])):
                                ^^^^^^^^^^^^^^^^^^^^^
AttributeError: 'ReturnList' object has no attribute 'get'
ERROR 2024-08-19 14:58:30,329 basehttp "POST /api/question/import_excel/ HTTP/1.1" 500 120090
ERROR 2024-08-19 15:01:33,470 log Internal Server Error: /api/question/import_excel/
Traceback (most recent call last):
  File "C:\Users\LENOVO\AppData\Roaming\Python\Python312\site-packages\django\core\handlers\exception.py", line 55, in inner
    response = get_response(request)
               ^^^^^^^^^^^^^^^^^^^^^
  File "C:\Users\LENOVO\AppData\Roaming\Python\Python312\site-packages\django\core\handlers\base.py", line 197, in _get_response
    response = wrapped_callback(request, *callback_args, **callback_kwargs)
               ^^^^^^^^^^^^^^^^^^^^^^^^^^^^^^^^^^^^^^^^^^^^^^^^^^^^^^^^^^^^
  File "C:\Users\LENOVO\AppData\Roaming\Python\Python312\site-packages\django\views\decorators\csrf.py", line 65, in _view_wrapper
    return view_func(request, *args, **kwargs)
           ^^^^^^^^^^^^^^^^^^^^^^^^^^^^^^^^^^^
  File "C:\Users\LENOVO\AppData\Roaming\Python\Python312\site-packages\django\views\generic\base.py", line 104, in view
    return self.dispatch(request, *args, **kwargs)
           ^^^^^^^^^^^^^^^^^^^^^^^^^^^^^^^^^^^^^^^
  File "C:\Users\LENOVO\AppData\Roaming\Python\Python312\site-packages\rest_framework\views.py", line 509, in dispatch
    response = self.handle_exception(exc)
               ^^^^^^^^^^^^^^^^^^^^^^^^^^
  File "C:\Users\LENOVO\AppData\Roaming\Python\Python312\site-packages\rest_framework\views.py", line 469, in handle_exception
    self.raise_uncaught_exception(exc)
  File "C:\Users\LENOVO\AppData\Roaming\Python\Python312\site-packages\rest_framework\views.py", line 480, in raise_uncaught_exception
    raise exc
  File "C:\Users\LENOVO\AppData\Roaming\Python\Python312\site-packages\rest_framework\views.py", line 506, in dispatch
    response = handler(request, *args, **kwargs)
               ^^^^^^^^^^^^^^^^^^^^^^^^^^^^^^^^^
  File "D:\V_Project\LMS-New\backend\app\views.py", line 2541, in post
    for idx, error in enumerate(serializer.errors.get('non_field_errors', [])):
                                ^^^^^^^^^^^^^^^^^^^^^
AttributeError: 'ReturnList' object has no attribute 'get'
ERROR 2024-08-19 15:01:33,860 basehttp "POST /api/question/import_excel/ HTTP/1.1" 500 120086
ERROR 2024-08-19 15:05:49,862 log Internal Server Error: /api/question/import_excel/
Traceback (most recent call last):
  File "C:\Users\LENOVO\AppData\Roaming\Python\Python312\site-packages\django\core\handlers\exception.py", line 55, in inner
    response = get_response(request)
               ^^^^^^^^^^^^^^^^^^^^^
  File "C:\Users\LENOVO\AppData\Roaming\Python\Python312\site-packages\django\core\handlers\base.py", line 197, in _get_response
    response = wrapped_callback(request, *callback_args, **callback_kwargs)
               ^^^^^^^^^^^^^^^^^^^^^^^^^^^^^^^^^^^^^^^^^^^^^^^^^^^^^^^^^^^^
  File "C:\Users\LENOVO\AppData\Roaming\Python\Python312\site-packages\django\views\decorators\csrf.py", line 65, in _view_wrapper
    return view_func(request, *args, **kwargs)
           ^^^^^^^^^^^^^^^^^^^^^^^^^^^^^^^^^^^
  File "C:\Users\LENOVO\AppData\Roaming\Python\Python312\site-packages\django\views\generic\base.py", line 104, in view
    return self.dispatch(request, *args, **kwargs)
           ^^^^^^^^^^^^^^^^^^^^^^^^^^^^^^^^^^^^^^^
  File "C:\Users\LENOVO\AppData\Roaming\Python\Python312\site-packages\rest_framework\views.py", line 509, in dispatch
    response = self.handle_exception(exc)
               ^^^^^^^^^^^^^^^^^^^^^^^^^^
  File "C:\Users\LENOVO\AppData\Roaming\Python\Python312\site-packages\rest_framework\views.py", line 469, in handle_exception
    self.raise_uncaught_exception(exc)
  File "C:\Users\LENOVO\AppData\Roaming\Python\Python312\site-packages\rest_framework\views.py", line 480, in raise_uncaught_exception
    raise exc
  File "C:\Users\LENOVO\AppData\Roaming\Python\Python312\site-packages\rest_framework\views.py", line 506, in dispatch
    response = handler(request, *args, **kwargs)
               ^^^^^^^^^^^^^^^^^^^^^^^^^^^^^^^^^
  File "D:\V_Project\LMS-New\backend\app\views.py", line 2543, in post
    non_field_errors = serializer.errors.get('non_field_errors', [])
                       ^^^^^^^^^^^^^^^^^^^^^
AttributeError: 'ReturnList' object has no attribute 'get'
ERROR 2024-08-19 15:05:50,341 basehttp "POST /api/question/import_excel/ HTTP/1.1" 500 119977
ERROR 2024-08-19 16:25:32,281 log Internal Server Error: /api/Candidate/import_excel/
Traceback (most recent call last):
  File "C:\Users\LENOVO\AppData\Roaming\Python\Python312\site-packages\django\core\handlers\exception.py", line 55, in inner
    response = get_response(request)
               ^^^^^^^^^^^^^^^^^^^^^
  File "C:\Users\LENOVO\AppData\Roaming\Python\Python312\site-packages\django\core\handlers\base.py", line 197, in _get_response
    response = wrapped_callback(request, *callback_args, **callback_kwargs)
               ^^^^^^^^^^^^^^^^^^^^^^^^^^^^^^^^^^^^^^^^^^^^^^^^^^^^^^^^^^^^
  File "C:\Users\LENOVO\AppData\Roaming\Python\Python312\site-packages\django\views\decorators\csrf.py", line 65, in _view_wrapper
    return view_func(request, *args, **kwargs)
           ^^^^^^^^^^^^^^^^^^^^^^^^^^^^^^^^^^^
  File "C:\Users\LENOVO\AppData\Roaming\Python\Python312\site-packages\django\views\generic\base.py", line 104, in view
    return self.dispatch(request, *args, **kwargs)
           ^^^^^^^^^^^^^^^^^^^^^^^^^^^^^^^^^^^^^^^
  File "C:\Users\LENOVO\AppData\Roaming\Python\Python312\site-packages\rest_framework\views.py", line 509, in dispatch
    response = self.handle_exception(exc)
               ^^^^^^^^^^^^^^^^^^^^^^^^^^
  File "C:\Users\LENOVO\AppData\Roaming\Python\Python312\site-packages\rest_framework\views.py", line 469, in handle_exception
    self.raise_uncaught_exception(exc)
  File "C:\Users\LENOVO\AppData\Roaming\Python\Python312\site-packages\rest_framework\views.py", line 480, in raise_uncaught_exception
    raise exc
  File "C:\Users\LENOVO\AppData\Roaming\Python\Python312\site-packages\rest_framework\views.py", line 506, in dispatch
    response = handler(request, *args, **kwargs)
               ^^^^^^^^^^^^^^^^^^^^^^^^^^^^^^^^^
  File "D:\V_Project\LMS-New\backend\app\views.py", line 2249, in post
    user_profile_serializer.save()
    ^^^^^^^^^^^^^^^^
NameError: name 'login_serializer' is not defined. Did you mean: 'loginSerializer'?
ERROR 2024-08-19 16:25:32,817 basehttp "POST /api/Candidate/import_excel/ HTTP/1.1" 500 113096
ERROR 2024-08-19 18:33:30,313 log Internal Server Error: /api/Candidate/user/import_excel/
Traceback (most recent call last):
  File "C:\Users\LENOVO\AppData\Roaming\Python\Python312\site-packages\pandas\core\indexes\base.py", line 3805, in get_loc
    return self._engine.get_loc(casted_key)
           ^^^^^^^^^^^^^^^^^^^^^^^^^^^^^^^^
  File "index.pyx", line 167, in pandas._libs.index.IndexEngine.get_loc
  File "index.pyx", line 196, in pandas._libs.index.IndexEngine.get_loc
  File "pandas\\_libs\\hashtable_class_helper.pxi", line 7081, in pandas._libs.hashtable.PyObjectHashTable.get_item
  File "pandas\\_libs\\hashtable_class_helper.pxi", line 7089, in pandas._libs.hashtable.PyObjectHashTable.get_item
KeyError: 'college_id'

The above exception was the direct cause of the following exception:

Traceback (most recent call last):
  File "C:\Users\LENOVO\AppData\Roaming\Python\Python312\site-packages\django\core\handlers\exception.py", line 55, in inner
    response = get_response(request)
               ^^^^^^^^^^^^^^^^^^^^^
  File "C:\Users\LENOVO\AppData\Roaming\Python\Python312\site-packages\django\core\handlers\base.py", line 197, in _get_response
    response = wrapped_callback(request, *callback_args, **callback_kwargs)
               ^^^^^^^^^^^^^^^^^^^^^^^^^^^^^^^^^^^^^^^^^^^^^^^^^^^^^^^^^^^^
  File "C:\Users\LENOVO\AppData\Roaming\Python\Python312\site-packages\django\views\decorators\csrf.py", line 65, in _view_wrapper
    return view_func(request, *args, **kwargs)
           ^^^^^^^^^^^^^^^^^^^^^^^^^^^^^^^^^^^
  File "C:\Users\LENOVO\AppData\Roaming\Python\Python312\site-packages\django\views\generic\base.py", line 104, in view
    return self.dispatch(request, *args, **kwargs)
           ^^^^^^^^^^^^^^^^^^^^^^^^^^^^^^^^^^^^^^^
  File "C:\Users\LENOVO\AppData\Roaming\Python\Python312\site-packages\rest_framework\views.py", line 509, in dispatch
    response = self.handle_exception(exc)
               ^^^^^^^^^^^^^^^^^^^^^^^^^^
  File "C:\Users\LENOVO\AppData\Roaming\Python\Python312\site-packages\rest_framework\views.py", line 469, in handle_exception
    self.raise_uncaught_exception(exc)
  File "C:\Users\LENOVO\AppData\Roaming\Python\Python312\site-packages\rest_framework\views.py", line 480, in raise_uncaught_exception
    raise exc
  File "C:\Users\LENOVO\AppData\Roaming\Python\Python312\site-packages\rest_framework\views.py", line 506, in dispatch
    response = handler(request, *args, **kwargs)
               ^^^^^^^^^^^^^^^^^^^^^^^^^^^^^^^^^
  File "D:\V_Project\LMS-New\backend\app\views.py", line 2363, in post
    df['college_id'] = df['college_id'].apply(get_college_id)
                       ~~^^^^^^^^^^^^^^
  File "C:\Users\LENOVO\AppData\Roaming\Python\Python312\site-packages\pandas\core\frame.py", line 4090, in __getitem__
    indexer = self.columns.get_loc(key)
              ^^^^^^^^^^^^^^^^^^^^^^^^^
  File "C:\Users\LENOVO\AppData\Roaming\Python\Python312\site-packages\pandas\core\indexes\base.py", line 3812, in get_loc
    raise KeyError(key) from err
KeyError: 'college_id'
ERROR 2024-08-19 18:33:30,798 basehttp "POST /api/Candidate/user/import_excel/ HTTP/1.1" 500 112175
ERROR 2024-08-19 18:34:44,857 log Internal Server Error: /api/nondb-candidates/
Traceback (most recent call last):
  File "C:\Users\LENOVO\AppData\Roaming\Python\Python312\site-packages\django\core\handlers\exception.py", line 55, in inner
    response = get_response(request)
               ^^^^^^^^^^^^^^^^^^^^^
  File "C:\Users\LENOVO\AppData\Roaming\Python\Python312\site-packages\django\core\handlers\base.py", line 197, in _get_response
    response = wrapped_callback(request, *callback_args, **callback_kwargs)
               ^^^^^^^^^^^^^^^^^^^^^^^^^^^^^^^^^^^^^^^^^^^^^^^^^^^^^^^^^^^^
  File "C:\Users\LENOVO\AppData\Roaming\Python\Python312\site-packages\django\views\decorators\csrf.py", line 65, in _view_wrapper
    return view_func(request, *args, **kwargs)
           ^^^^^^^^^^^^^^^^^^^^^^^^^^^^^^^^^^^
  File "C:\Users\LENOVO\AppData\Roaming\Python\Python312\site-packages\django\views\generic\base.py", line 104, in view
    return self.dispatch(request, *args, **kwargs)
           ^^^^^^^^^^^^^^^^^^^^^^^^^^^^^^^^^^^^^^^
  File "C:\Users\LENOVO\AppData\Roaming\Python\Python312\site-packages\rest_framework\views.py", line 509, in dispatch
    response = self.handle_exception(exc)
               ^^^^^^^^^^^^^^^^^^^^^^^^^^
  File "C:\Users\LENOVO\AppData\Roaming\Python\Python312\site-packages\rest_framework\views.py", line 469, in handle_exception
    self.raise_uncaught_exception(exc)
  File "C:\Users\LENOVO\AppData\Roaming\Python\Python312\site-packages\rest_framework\views.py", line 480, in raise_uncaught_exception
    raise exc
  File "C:\Users\LENOVO\AppData\Roaming\Python\Python312\site-packages\rest_framework\views.py", line 506, in dispatch
    response = handler(request, *args, **kwargs)
               ^^^^^^^^^^^^^^^^^^^^^^^^^^^^^^^^^
  File "C:\Users\LENOVO\AppData\Roaming\Python\Python312\site-packages\rest_framework\decorators.py", line 50, in handler
    return func(*args, **kwargs)
           ^^^^^^^^^^^^^^^^^^^^^
  File "D:\V_Project\LMS-New\backend\app\views.py", line 7516, in get_nondb_candidate
    nondatabase_candidates = login.objects.filter(
                             ^^^^^^^^^^^^^
AttributeError: 'function' object has no attribute 'objects'
ERROR 2024-08-19 18:34:45,027 basehttp "GET /api/nondb-candidates/ HTTP/1.1" 500 99789
ERROR 2024-08-19 18:34:47,672 log Internal Server Error: /api/nondb-candidates/
Traceback (most recent call last):
  File "C:\Users\LENOVO\AppData\Roaming\Python\Python312\site-packages\django\core\handlers\exception.py", line 55, in inner
    response = get_response(request)
               ^^^^^^^^^^^^^^^^^^^^^
  File "C:\Users\LENOVO\AppData\Roaming\Python\Python312\site-packages\django\core\handlers\base.py", line 197, in _get_response
    response = wrapped_callback(request, *callback_args, **callback_kwargs)
               ^^^^^^^^^^^^^^^^^^^^^^^^^^^^^^^^^^^^^^^^^^^^^^^^^^^^^^^^^^^^
  File "C:\Users\LENOVO\AppData\Roaming\Python\Python312\site-packages\django\views\decorators\csrf.py", line 65, in _view_wrapper
    return view_func(request, *args, **kwargs)
           ^^^^^^^^^^^^^^^^^^^^^^^^^^^^^^^^^^^
  File "C:\Users\LENOVO\AppData\Roaming\Python\Python312\site-packages\django\views\generic\base.py", line 104, in view
    return self.dispatch(request, *args, **kwargs)
           ^^^^^^^^^^^^^^^^^^^^^^^^^^^^^^^^^^^^^^^
  File "C:\Users\LENOVO\AppData\Roaming\Python\Python312\site-packages\rest_framework\views.py", line 509, in dispatch
    response = self.handle_exception(exc)
               ^^^^^^^^^^^^^^^^^^^^^^^^^^
  File "C:\Users\LENOVO\AppData\Roaming\Python\Python312\site-packages\rest_framework\views.py", line 469, in handle_exception
    self.raise_uncaught_exception(exc)
  File "C:\Users\LENOVO\AppData\Roaming\Python\Python312\site-packages\rest_framework\views.py", line 480, in raise_uncaught_exception
    raise exc
  File "C:\Users\LENOVO\AppData\Roaming\Python\Python312\site-packages\rest_framework\views.py", line 506, in dispatch
    response = handler(request, *args, **kwargs)
               ^^^^^^^^^^^^^^^^^^^^^^^^^^^^^^^^^
  File "C:\Users\LENOVO\AppData\Roaming\Python\Python312\site-packages\rest_framework\decorators.py", line 50, in handler
    return func(*args, **kwargs)
           ^^^^^^^^^^^^^^^^^^^^^
  File "D:\V_Project\LMS-New\backend\app\views.py", line 7516, in get_nondb_candidate
    nondatabase_candidates = login.objects.filter(
                             ^^^^^^^^^^^^^
AttributeError: 'function' object has no attribute 'objects'
ERROR 2024-08-19 18:34:47,892 basehttp "GET /api/nondb-candidates/ HTTP/1.1" 500 99789
ERROR 2024-08-19 18:35:36,709 log Internal Server Error: /api/nondb-candidates/
Traceback (most recent call last):
  File "C:\Users\LENOVO\AppData\Roaming\Python\Python312\site-packages\django\core\handlers\exception.py", line 55, in inner
    response = get_response(request)
               ^^^^^^^^^^^^^^^^^^^^^
  File "C:\Users\LENOVO\AppData\Roaming\Python\Python312\site-packages\django\core\handlers\base.py", line 197, in _get_response
    response = wrapped_callback(request, *callback_args, **callback_kwargs)
               ^^^^^^^^^^^^^^^^^^^^^^^^^^^^^^^^^^^^^^^^^^^^^^^^^^^^^^^^^^^^
  File "C:\Users\LENOVO\AppData\Roaming\Python\Python312\site-packages\django\views\decorators\csrf.py", line 65, in _view_wrapper
    return view_func(request, *args, **kwargs)
           ^^^^^^^^^^^^^^^^^^^^^^^^^^^^^^^^^^^
  File "C:\Users\LENOVO\AppData\Roaming\Python\Python312\site-packages\django\views\generic\base.py", line 104, in view
    return self.dispatch(request, *args, **kwargs)
           ^^^^^^^^^^^^^^^^^^^^^^^^^^^^^^^^^^^^^^^
  File "C:\Users\LENOVO\AppData\Roaming\Python\Python312\site-packages\rest_framework\views.py", line 509, in dispatch
    response = self.handle_exception(exc)
               ^^^^^^^^^^^^^^^^^^^^^^^^^^
  File "C:\Users\LENOVO\AppData\Roaming\Python\Python312\site-packages\rest_framework\views.py", line 469, in handle_exception
    self.raise_uncaught_exception(exc)
  File "C:\Users\LENOVO\AppData\Roaming\Python\Python312\site-packages\rest_framework\views.py", line 480, in raise_uncaught_exception
    raise exc
  File "C:\Users\LENOVO\AppData\Roaming\Python\Python312\site-packages\rest_framework\views.py", line 506, in dispatch
    response = handler(request, *args, **kwargs)
               ^^^^^^^^^^^^^^^^^^^^^^^^^^^^^^^^^
  File "C:\Users\LENOVO\AppData\Roaming\Python\Python312\site-packages\rest_framework\decorators.py", line 50, in handler
    return func(*args, **kwargs)
           ^^^^^^^^^^^^^^^^^^^^^
  File "D:\V_Project\LMS-New\backend\app\views.py", line 7516, in get_nondb_candidate
    nondatabase_candidates = login.objects.filter(
                             ^^^^^^^^^^^^^
AttributeError: 'function' object has no attribute 'objects'
ERROR 2024-08-19 18:35:36,941 basehttp "GET /api/nondb-candidates/ HTTP/1.1" 500 99789
ERROR 2024-08-19 18:35:39,177 log Internal Server Error: /api/nondb-candidates/
Traceback (most recent call last):
  File "C:\Users\LENOVO\AppData\Roaming\Python\Python312\site-packages\django\core\handlers\exception.py", line 55, in inner
    response = get_response(request)
               ^^^^^^^^^^^^^^^^^^^^^
  File "C:\Users\LENOVO\AppData\Roaming\Python\Python312\site-packages\django\core\handlers\base.py", line 197, in _get_response
    response = wrapped_callback(request, *callback_args, **callback_kwargs)
               ^^^^^^^^^^^^^^^^^^^^^^^^^^^^^^^^^^^^^^^^^^^^^^^^^^^^^^^^^^^^
  File "C:\Users\LENOVO\AppData\Roaming\Python\Python312\site-packages\django\views\decorators\csrf.py", line 65, in _view_wrapper
    return view_func(request, *args, **kwargs)
           ^^^^^^^^^^^^^^^^^^^^^^^^^^^^^^^^^^^
  File "C:\Users\LENOVO\AppData\Roaming\Python\Python312\site-packages\django\views\generic\base.py", line 104, in view
    return self.dispatch(request, *args, **kwargs)
           ^^^^^^^^^^^^^^^^^^^^^^^^^^^^^^^^^^^^^^^
  File "C:\Users\LENOVO\AppData\Roaming\Python\Python312\site-packages\rest_framework\views.py", line 509, in dispatch
    response = self.handle_exception(exc)
               ^^^^^^^^^^^^^^^^^^^^^^^^^^
  File "C:\Users\LENOVO\AppData\Roaming\Python\Python312\site-packages\rest_framework\views.py", line 469, in handle_exception
    self.raise_uncaught_exception(exc)
  File "C:\Users\LENOVO\AppData\Roaming\Python\Python312\site-packages\rest_framework\views.py", line 480, in raise_uncaught_exception
    raise exc
  File "C:\Users\LENOVO\AppData\Roaming\Python\Python312\site-packages\rest_framework\views.py", line 506, in dispatch
    response = handler(request, *args, **kwargs)
               ^^^^^^^^^^^^^^^^^^^^^^^^^^^^^^^^^
  File "C:\Users\LENOVO\AppData\Roaming\Python\Python312\site-packages\rest_framework\decorators.py", line 50, in handler
    return func(*args, **kwargs)
           ^^^^^^^^^^^^^^^^^^^^^
  File "D:\V_Project\LMS-New\backend\app\views.py", line 7516, in get_nondb_candidate
    nondatabase_candidates = login.objects.filter(
                             ^^^^^^^^^^^^^
AttributeError: 'function' object has no attribute 'objects'
ERROR 2024-08-19 18:35:39,406 basehttp "GET /api/nondb-candidates/ HTTP/1.1" 500 99789
ERROR 2024-08-19 18:35:45,264 log Internal Server Error: /api/Candidate/user/import_excel/
Traceback (most recent call last):
  File "C:\Users\LENOVO\AppData\Roaming\Python\Python312\site-packages\django\core\handlers\exception.py", line 55, in inner
    response = get_response(request)
               ^^^^^^^^^^^^^^^^^^^^^
  File "C:\Users\LENOVO\AppData\Roaming\Python\Python312\site-packages\django\core\handlers\base.py", line 197, in _get_response
    response = wrapped_callback(request, *callback_args, **callback_kwargs)
               ^^^^^^^^^^^^^^^^^^^^^^^^^^^^^^^^^^^^^^^^^^^^^^^^^^^^^^^^^^^^
  File "C:\Users\LENOVO\AppData\Roaming\Python\Python312\site-packages\django\views\decorators\csrf.py", line 65, in _view_wrapper
    return view_func(request, *args, **kwargs)
           ^^^^^^^^^^^^^^^^^^^^^^^^^^^^^^^^^^^
  File "C:\Users\LENOVO\AppData\Roaming\Python\Python312\site-packages\django\views\generic\base.py", line 104, in view
    return self.dispatch(request, *args, **kwargs)
           ^^^^^^^^^^^^^^^^^^^^^^^^^^^^^^^^^^^^^^^
  File "C:\Users\LENOVO\AppData\Roaming\Python\Python312\site-packages\rest_framework\views.py", line 509, in dispatch
    response = self.handle_exception(exc)
               ^^^^^^^^^^^^^^^^^^^^^^^^^^
  File "C:\Users\LENOVO\AppData\Roaming\Python\Python312\site-packages\rest_framework\views.py", line 469, in handle_exception
    self.raise_uncaught_exception(exc)
  File "C:\Users\LENOVO\AppData\Roaming\Python\Python312\site-packages\rest_framework\views.py", line 480, in raise_uncaught_exception
    raise exc
  File "C:\Users\LENOVO\AppData\Roaming\Python\Python312\site-packages\rest_framework\views.py", line 506, in dispatch
    response = handler(request, *args, **kwargs)
               ^^^^^^^^^^^^^^^^^^^^^^^^^^^^^^^^^
  File "D:\V_Project\LMS-New\backend\app\views.py", line 2390, in post
    user = User.objects.create_user(
           ^^^^^^^^^^^^^^^^^^^^^^^^^
  File "C:\Users\LENOVO\AppData\Roaming\Python\Python312\site-packages\django\contrib\auth\models.py", line 161, in create_user
    return self._create_user(username, email, password, **extra_fields)
           ^^^^^^^^^^^^^^^^^^^^^^^^^^^^^^^^^^^^^^^^^^^^^^^^^^^^^^^^^^^^
  File "C:\Users\LENOVO\AppData\Roaming\Python\Python312\site-packages\django\contrib\auth\models.py", line 154, in _create_user
    user.password = make_password(password)
                    ^^^^^^^^^^^^^^^^^^^^^^^
  File "C:\Users\LENOVO\AppData\Roaming\Python\Python312\site-packages\django\contrib\auth\hashers.py", line 103, in make_password
    raise TypeError(
TypeError: Password must be a string or bytes, got int.
ERROR 2024-08-19 18:35:45,408 basehttp "POST /api/Candidate/user/import_excel/ HTTP/1.1" 500 111716
ERROR 2024-08-19 19:04:30,008 log Internal Server Error: /api/nondb-candidates/
Traceback (most recent call last):
  File "C:\Users\LENOVO\AppData\Roaming\Python\Python312\site-packages\django\core\handlers\exception.py", line 55, in inner
    response = get_response(request)
               ^^^^^^^^^^^^^^^^^^^^^
  File "C:\Users\LENOVO\AppData\Roaming\Python\Python312\site-packages\django\core\handlers\base.py", line 197, in _get_response
    response = wrapped_callback(request, *callback_args, **callback_kwargs)
               ^^^^^^^^^^^^^^^^^^^^^^^^^^^^^^^^^^^^^^^^^^^^^^^^^^^^^^^^^^^^
  File "C:\Users\LENOVO\AppData\Roaming\Python\Python312\site-packages\django\views\decorators\csrf.py", line 65, in _view_wrapper
    return view_func(request, *args, **kwargs)
           ^^^^^^^^^^^^^^^^^^^^^^^^^^^^^^^^^^^
  File "C:\Users\LENOVO\AppData\Roaming\Python\Python312\site-packages\django\views\generic\base.py", line 104, in view
    return self.dispatch(request, *args, **kwargs)
           ^^^^^^^^^^^^^^^^^^^^^^^^^^^^^^^^^^^^^^^
  File "C:\Users\LENOVO\AppData\Roaming\Python\Python312\site-packages\rest_framework\views.py", line 509, in dispatch
    response = self.handle_exception(exc)
               ^^^^^^^^^^^^^^^^^^^^^^^^^^
  File "C:\Users\LENOVO\AppData\Roaming\Python\Python312\site-packages\rest_framework\views.py", line 469, in handle_exception
    self.raise_uncaught_exception(exc)
  File "C:\Users\LENOVO\AppData\Roaming\Python\Python312\site-packages\rest_framework\views.py", line 480, in raise_uncaught_exception
    raise exc
  File "C:\Users\LENOVO\AppData\Roaming\Python\Python312\site-packages\rest_framework\views.py", line 506, in dispatch
    response = handler(request, *args, **kwargs)
               ^^^^^^^^^^^^^^^^^^^^^^^^^^^^^^^^^
  File "C:\Users\LENOVO\AppData\Roaming\Python\Python312\site-packages\rest_framework\decorators.py", line 50, in handler
    return func(*args, **kwargs)
           ^^^^^^^^^^^^^^^^^^^^^
  File "D:\V_Project\LMS-New\backend\app\views.py", line 7519, in get_nondb_candidate
    nondatabase_candidates = login.objects.filter(
                             ^^^^^^^^^^^^^
AttributeError: 'function' object has no attribute 'objects'
ERROR 2024-08-19 19:04:30,465 basehttp "GET /api/nondb-candidates/ HTTP/1.1" 500 99789
ERROR 2024-08-19 19:04:31,679 log Internal Server Error: /api/nondb-candidates/
Traceback (most recent call last):
  File "C:\Users\LENOVO\AppData\Roaming\Python\Python312\site-packages\django\core\handlers\exception.py", line 55, in inner
    response = get_response(request)
               ^^^^^^^^^^^^^^^^^^^^^
  File "C:\Users\LENOVO\AppData\Roaming\Python\Python312\site-packages\django\core\handlers\base.py", line 197, in _get_response
    response = wrapped_callback(request, *callback_args, **callback_kwargs)
               ^^^^^^^^^^^^^^^^^^^^^^^^^^^^^^^^^^^^^^^^^^^^^^^^^^^^^^^^^^^^
  File "C:\Users\LENOVO\AppData\Roaming\Python\Python312\site-packages\django\views\decorators\csrf.py", line 65, in _view_wrapper
    return view_func(request, *args, **kwargs)
           ^^^^^^^^^^^^^^^^^^^^^^^^^^^^^^^^^^^
  File "C:\Users\LENOVO\AppData\Roaming\Python\Python312\site-packages\django\views\generic\base.py", line 104, in view
    return self.dispatch(request, *args, **kwargs)
           ^^^^^^^^^^^^^^^^^^^^^^^^^^^^^^^^^^^^^^^
  File "C:\Users\LENOVO\AppData\Roaming\Python\Python312\site-packages\rest_framework\views.py", line 509, in dispatch
    response = self.handle_exception(exc)
               ^^^^^^^^^^^^^^^^^^^^^^^^^^
  File "C:\Users\LENOVO\AppData\Roaming\Python\Python312\site-packages\rest_framework\views.py", line 469, in handle_exception
    self.raise_uncaught_exception(exc)
  File "C:\Users\LENOVO\AppData\Roaming\Python\Python312\site-packages\rest_framework\views.py", line 480, in raise_uncaught_exception
    raise exc
  File "C:\Users\LENOVO\AppData\Roaming\Python\Python312\site-packages\rest_framework\views.py", line 506, in dispatch
    response = handler(request, *args, **kwargs)
               ^^^^^^^^^^^^^^^^^^^^^^^^^^^^^^^^^
  File "C:\Users\LENOVO\AppData\Roaming\Python\Python312\site-packages\rest_framework\decorators.py", line 50, in handler
    return func(*args, **kwargs)
           ^^^^^^^^^^^^^^^^^^^^^
  File "D:\V_Project\LMS-New\backend\app\views.py", line 7519, in get_nondb_candidate
    nondatabase_candidates = login.objects.filter(
                             ^^^^^^^^^^^^^
AttributeError: 'function' object has no attribute 'objects'
ERROR 2024-08-19 19:04:31,933 basehttp "GET /api/nondb-candidates/ HTTP/1.1" 500 99789
ERROR 2024-08-19 19:04:43,858 log Internal Server Error: /api/Candidate/user/import_excel/
Traceback (most recent call last):
  File "C:\Users\LENOVO\AppData\Roaming\Python\Python312\site-packages\django\core\handlers\exception.py", line 55, in inner
    response = get_response(request)
               ^^^^^^^^^^^^^^^^^^^^^
  File "C:\Users\LENOVO\AppData\Roaming\Python\Python312\site-packages\django\core\handlers\base.py", line 197, in _get_response
    response = wrapped_callback(request, *callback_args, **callback_kwargs)
               ^^^^^^^^^^^^^^^^^^^^^^^^^^^^^^^^^^^^^^^^^^^^^^^^^^^^^^^^^^^^
  File "C:\Users\LENOVO\AppData\Roaming\Python\Python312\site-packages\django\views\decorators\csrf.py", line 65, in _view_wrapper
    return view_func(request, *args, **kwargs)
           ^^^^^^^^^^^^^^^^^^^^^^^^^^^^^^^^^^^
  File "C:\Users\LENOVO\AppData\Roaming\Python\Python312\site-packages\django\views\generic\base.py", line 104, in view
    return self.dispatch(request, *args, **kwargs)
           ^^^^^^^^^^^^^^^^^^^^^^^^^^^^^^^^^^^^^^^
  File "C:\Users\LENOVO\AppData\Roaming\Python\Python312\site-packages\rest_framework\views.py", line 509, in dispatch
    response = self.handle_exception(exc)
               ^^^^^^^^^^^^^^^^^^^^^^^^^^
  File "C:\Users\LENOVO\AppData\Roaming\Python\Python312\site-packages\rest_framework\views.py", line 469, in handle_exception
    self.raise_uncaught_exception(exc)
  File "C:\Users\LENOVO\AppData\Roaming\Python\Python312\site-packages\rest_framework\views.py", line 480, in raise_uncaught_exception
    raise exc
  File "C:\Users\LENOVO\AppData\Roaming\Python\Python312\site-packages\rest_framework\views.py", line 506, in dispatch
    response = handler(request, *args, **kwargs)
               ^^^^^^^^^^^^^^^^^^^^^^^^^^^^^^^^^
  File "D:\V_Project\LMS-New\backend\app\views.py", line 2399, in post
    user_profile.objects.create(
  File "C:\Users\LENOVO\AppData\Roaming\Python\Python312\site-packages\django\db\models\manager.py", line 87, in manager_method
    return getattr(self.get_queryset(), name)(*args, **kwargs)
           ^^^^^^^^^^^^^^^^^^^^^^^^^^^^^^^^^^^^^^^^^^^^^^^^^^^
  File "C:\Users\LENOVO\AppData\Roaming\Python\Python312\site-packages\django\db\models\query.py", line 677, in create
    obj = self.model(**kwargs)
          ^^^^^^^^^^^^^^^^^^^^
  File "C:\Users\LENOVO\AppData\Roaming\Python\Python312\site-packages\django\db\models\base.py", line 543, in __init__
    _setattr(self, field.name, rel_obj)
  File "C:\Users\LENOVO\AppData\Roaming\Python\Python312\site-packages\django\db\models\fields\related_descriptors.py", line 284, in __set__
    raise ValueError(
ValueError: Cannot assign "1": "user_profile.college_id" must be a "college_master" instance.
ERROR 2024-08-19 19:04:44,112 basehttp "POST /api/Candidate/user/import_excel/ HTTP/1.1" 500 117632
ERROR 2024-08-19 19:05:40,152 log Internal Server Error: /api/nondb-candidates/
Traceback (most recent call last):
  File "C:\Users\LENOVO\AppData\Roaming\Python\Python312\site-packages\django\core\handlers\exception.py", line 55, in inner
    response = get_response(request)
               ^^^^^^^^^^^^^^^^^^^^^
  File "C:\Users\LENOVO\AppData\Roaming\Python\Python312\site-packages\django\core\handlers\base.py", line 197, in _get_response
    response = wrapped_callback(request, *callback_args, **callback_kwargs)
               ^^^^^^^^^^^^^^^^^^^^^^^^^^^^^^^^^^^^^^^^^^^^^^^^^^^^^^^^^^^^
  File "C:\Users\LENOVO\AppData\Roaming\Python\Python312\site-packages\django\views\decorators\csrf.py", line 65, in _view_wrapper
    return view_func(request, *args, **kwargs)
           ^^^^^^^^^^^^^^^^^^^^^^^^^^^^^^^^^^^
  File "C:\Users\LENOVO\AppData\Roaming\Python\Python312\site-packages\django\views\generic\base.py", line 104, in view
    return self.dispatch(request, *args, **kwargs)
           ^^^^^^^^^^^^^^^^^^^^^^^^^^^^^^^^^^^^^^^
  File "C:\Users\LENOVO\AppData\Roaming\Python\Python312\site-packages\rest_framework\views.py", line 509, in dispatch
    response = self.handle_exception(exc)
               ^^^^^^^^^^^^^^^^^^^^^^^^^^
  File "C:\Users\LENOVO\AppData\Roaming\Python\Python312\site-packages\rest_framework\views.py", line 469, in handle_exception
    self.raise_uncaught_exception(exc)
  File "C:\Users\LENOVO\AppData\Roaming\Python\Python312\site-packages\rest_framework\views.py", line 480, in raise_uncaught_exception
    raise exc
  File "C:\Users\LENOVO\AppData\Roaming\Python\Python312\site-packages\rest_framework\views.py", line 506, in dispatch
    response = handler(request, *args, **kwargs)
               ^^^^^^^^^^^^^^^^^^^^^^^^^^^^^^^^^
  File "C:\Users\LENOVO\AppData\Roaming\Python\Python312\site-packages\rest_framework\decorators.py", line 50, in handler
    return func(*args, **kwargs)
           ^^^^^^^^^^^^^^^^^^^^^
  File "D:\V_Project\LMS-New\backend\app\views.py", line 7519, in get_nondb_candidate
    nondatabase_candidates = login.objects.filter(
                             ^^^^^^^^^^^^^
AttributeError: 'function' object has no attribute 'objects'
ERROR 2024-08-19 19:05:40,254 basehttp "GET /api/nondb-candidates/ HTTP/1.1" 500 99789
ERROR 2024-08-19 19:05:42,089 log Internal Server Error: /api/nondb-candidates/
Traceback (most recent call last):
  File "C:\Users\LENOVO\AppData\Roaming\Python\Python312\site-packages\django\core\handlers\exception.py", line 55, in inner
    response = get_response(request)
               ^^^^^^^^^^^^^^^^^^^^^
  File "C:\Users\LENOVO\AppData\Roaming\Python\Python312\site-packages\django\core\handlers\base.py", line 197, in _get_response
    response = wrapped_callback(request, *callback_args, **callback_kwargs)
               ^^^^^^^^^^^^^^^^^^^^^^^^^^^^^^^^^^^^^^^^^^^^^^^^^^^^^^^^^^^^
  File "C:\Users\LENOVO\AppData\Roaming\Python\Python312\site-packages\django\views\decorators\csrf.py", line 65, in _view_wrapper
    return view_func(request, *args, **kwargs)
           ^^^^^^^^^^^^^^^^^^^^^^^^^^^^^^^^^^^
  File "C:\Users\LENOVO\AppData\Roaming\Python\Python312\site-packages\django\views\generic\base.py", line 104, in view
    return self.dispatch(request, *args, **kwargs)
           ^^^^^^^^^^^^^^^^^^^^^^^^^^^^^^^^^^^^^^^
  File "C:\Users\LENOVO\AppData\Roaming\Python\Python312\site-packages\rest_framework\views.py", line 509, in dispatch
    response = self.handle_exception(exc)
               ^^^^^^^^^^^^^^^^^^^^^^^^^^
  File "C:\Users\LENOVO\AppData\Roaming\Python\Python312\site-packages\rest_framework\views.py", line 469, in handle_exception
    self.raise_uncaught_exception(exc)
  File "C:\Users\LENOVO\AppData\Roaming\Python\Python312\site-packages\rest_framework\views.py", line 480, in raise_uncaught_exception
    raise exc
  File "C:\Users\LENOVO\AppData\Roaming\Python\Python312\site-packages\rest_framework\views.py", line 506, in dispatch
    response = handler(request, *args, **kwargs)
               ^^^^^^^^^^^^^^^^^^^^^^^^^^^^^^^^^
  File "C:\Users\LENOVO\AppData\Roaming\Python\Python312\site-packages\rest_framework\decorators.py", line 50, in handler
    return func(*args, **kwargs)
           ^^^^^^^^^^^^^^^^^^^^^
  File "D:\V_Project\LMS-New\backend\app\views.py", line 7519, in get_nondb_candidate
    nondatabase_candidates = login.objects.filter(
                             ^^^^^^^^^^^^^
AttributeError: 'function' object has no attribute 'objects'
ERROR 2024-08-19 19:05:42,355 basehttp "GET /api/nondb-candidates/ HTTP/1.1" 500 99789
ERROR 2024-08-19 19:07:56,974 log Internal Server Error: /api/Candidate/user/import_excel/
Traceback (most recent call last):
  File "C:\Users\LENOVO\AppData\Roaming\Python\Python312\site-packages\django\core\handlers\exception.py", line 55, in inner
    response = get_response(request)
               ^^^^^^^^^^^^^^^^^^^^^
  File "C:\Users\LENOVO\AppData\Roaming\Python\Python312\site-packages\django\core\handlers\base.py", line 197, in _get_response
    response = wrapped_callback(request, *callback_args, **callback_kwargs)
               ^^^^^^^^^^^^^^^^^^^^^^^^^^^^^^^^^^^^^^^^^^^^^^^^^^^^^^^^^^^^
  File "C:\Users\LENOVO\AppData\Roaming\Python\Python312\site-packages\django\views\decorators\csrf.py", line 65, in _view_wrapper
    return view_func(request, *args, **kwargs)
           ^^^^^^^^^^^^^^^^^^^^^^^^^^^^^^^^^^^
  File "C:\Users\LENOVO\AppData\Roaming\Python\Python312\site-packages\django\views\generic\base.py", line 104, in view
    return self.dispatch(request, *args, **kwargs)
           ^^^^^^^^^^^^^^^^^^^^^^^^^^^^^^^^^^^^^^^
  File "C:\Users\LENOVO\AppData\Roaming\Python\Python312\site-packages\rest_framework\views.py", line 509, in dispatch
    response = self.handle_exception(exc)
               ^^^^^^^^^^^^^^^^^^^^^^^^^^
  File "C:\Users\LENOVO\AppData\Roaming\Python\Python312\site-packages\rest_framework\views.py", line 469, in handle_exception
    self.raise_uncaught_exception(exc)
  File "C:\Users\LENOVO\AppData\Roaming\Python\Python312\site-packages\rest_framework\views.py", line 480, in raise_uncaught_exception
    raise exc
  File "C:\Users\LENOVO\AppData\Roaming\Python\Python312\site-packages\rest_framework\views.py", line 506, in dispatch
    response = handler(request, *args, **kwargs)
               ^^^^^^^^^^^^^^^^^^^^^^^^^^^^^^^^^
  File "D:\V_Project\LMS-New\backend\app\views.py", line 2400, in post
    user_profile.objects.create(
  File "C:\Users\LENOVO\AppData\Roaming\Python\Python312\site-packages\django\db\models\manager.py", line 87, in manager_method
    return getattr(self.get_queryset(), name)(*args, **kwargs)
           ^^^^^^^^^^^^^^^^^^^^^^^^^^^^^^^^^^^^^^^^^^^^^^^^^^^
  File "C:\Users\LENOVO\AppData\Roaming\Python\Python312\site-packages\django\db\models\query.py", line 677, in create
    obj = self.model(**kwargs)
          ^^^^^^^^^^^^^^^^^^^^
  File "C:\Users\LENOVO\AppData\Roaming\Python\Python312\site-packages\django\db\models\base.py", line 543, in __init__
    _setattr(self, field.name, rel_obj)
  File "C:\Users\LENOVO\AppData\Roaming\Python\Python312\site-packages\django\db\models\fields\related_descriptors.py", line 284, in __set__
    raise ValueError(
ValueError: Cannot assign "1": "user_profile.college_id" must be a "college_master" instance.
ERROR 2024-08-19 19:07:57,305 basehttp "POST /api/Candidate/user/import_excel/ HTTP/1.1" 500 117632
ERROR 2024-08-19 19:15:49,940 log Internal Server Error: /api/nondb-candidates/
Traceback (most recent call last):
  File "C:\Users\LENOVO\AppData\Roaming\Python\Python312\site-packages\django\core\handlers\exception.py", line 55, in inner
    response = get_response(request)
               ^^^^^^^^^^^^^^^^^^^^^
  File "C:\Users\LENOVO\AppData\Roaming\Python\Python312\site-packages\django\core\handlers\base.py", line 197, in _get_response
    response = wrapped_callback(request, *callback_args, **callback_kwargs)
               ^^^^^^^^^^^^^^^^^^^^^^^^^^^^^^^^^^^^^^^^^^^^^^^^^^^^^^^^^^^^
  File "C:\Users\LENOVO\AppData\Roaming\Python\Python312\site-packages\django\views\decorators\csrf.py", line 65, in _view_wrapper
    return view_func(request, *args, **kwargs)
           ^^^^^^^^^^^^^^^^^^^^^^^^^^^^^^^^^^^
  File "C:\Users\LENOVO\AppData\Roaming\Python\Python312\site-packages\django\views\generic\base.py", line 104, in view
    return self.dispatch(request, *args, **kwargs)
           ^^^^^^^^^^^^^^^^^^^^^^^^^^^^^^^^^^^^^^^
  File "C:\Users\LENOVO\AppData\Roaming\Python\Python312\site-packages\rest_framework\views.py", line 509, in dispatch
    response = self.handle_exception(exc)
               ^^^^^^^^^^^^^^^^^^^^^^^^^^
  File "C:\Users\LENOVO\AppData\Roaming\Python\Python312\site-packages\rest_framework\views.py", line 469, in handle_exception
    self.raise_uncaught_exception(exc)
  File "C:\Users\LENOVO\AppData\Roaming\Python\Python312\site-packages\rest_framework\views.py", line 480, in raise_uncaught_exception
    raise exc
  File "C:\Users\LENOVO\AppData\Roaming\Python\Python312\site-packages\rest_framework\views.py", line 506, in dispatch
    response = handler(request, *args, **kwargs)
               ^^^^^^^^^^^^^^^^^^^^^^^^^^^^^^^^^
  File "C:\Users\LENOVO\AppData\Roaming\Python\Python312\site-packages\rest_framework\decorators.py", line 50, in handler
    return func(*args, **kwargs)
           ^^^^^^^^^^^^^^^^^^^^^
  File "D:\V_Project\LMS-New\backend\app\views.py", line 7526, in get_nondb_candidate
    nondatabase_candidates = login.objects.filter(
                             ^^^^^^^^^^^^^
AttributeError: 'function' object has no attribute 'objects'
ERROR 2024-08-19 19:15:50,519 basehttp "GET /api/nondb-candidates/ HTTP/1.1" 500 99789
ERROR 2024-08-19 19:15:52,778 log Internal Server Error: /api/nondb-candidates/
Traceback (most recent call last):
  File "C:\Users\LENOVO\AppData\Roaming\Python\Python312\site-packages\django\core\handlers\exception.py", line 55, in inner
    response = get_response(request)
               ^^^^^^^^^^^^^^^^^^^^^
  File "C:\Users\LENOVO\AppData\Roaming\Python\Python312\site-packages\django\core\handlers\base.py", line 197, in _get_response
    response = wrapped_callback(request, *callback_args, **callback_kwargs)
               ^^^^^^^^^^^^^^^^^^^^^^^^^^^^^^^^^^^^^^^^^^^^^^^^^^^^^^^^^^^^
  File "C:\Users\LENOVO\AppData\Roaming\Python\Python312\site-packages\django\views\decorators\csrf.py", line 65, in _view_wrapper
    return view_func(request, *args, **kwargs)
           ^^^^^^^^^^^^^^^^^^^^^^^^^^^^^^^^^^^
  File "C:\Users\LENOVO\AppData\Roaming\Python\Python312\site-packages\django\views\generic\base.py", line 104, in view
    return self.dispatch(request, *args, **kwargs)
           ^^^^^^^^^^^^^^^^^^^^^^^^^^^^^^^^^^^^^^^
  File "C:\Users\LENOVO\AppData\Roaming\Python\Python312\site-packages\rest_framework\views.py", line 509, in dispatch
    response = self.handle_exception(exc)
               ^^^^^^^^^^^^^^^^^^^^^^^^^^
  File "C:\Users\LENOVO\AppData\Roaming\Python\Python312\site-packages\rest_framework\views.py", line 469, in handle_exception
    self.raise_uncaught_exception(exc)
  File "C:\Users\LENOVO\AppData\Roaming\Python\Python312\site-packages\rest_framework\views.py", line 480, in raise_uncaught_exception
    raise exc
  File "C:\Users\LENOVO\AppData\Roaming\Python\Python312\site-packages\rest_framework\views.py", line 506, in dispatch
    response = handler(request, *args, **kwargs)
               ^^^^^^^^^^^^^^^^^^^^^^^^^^^^^^^^^
  File "C:\Users\LENOVO\AppData\Roaming\Python\Python312\site-packages\rest_framework\decorators.py", line 50, in handler
    return func(*args, **kwargs)
           ^^^^^^^^^^^^^^^^^^^^^
  File "D:\V_Project\LMS-New\backend\app\views.py", line 7526, in get_nondb_candidate
    nondatabase_candidates = login.objects.filter(
                             ^^^^^^^^^^^^^
AttributeError: 'function' object has no attribute 'objects'
ERROR 2024-08-19 19:15:52,936 basehttp "GET /api/nondb-candidates/ HTTP/1.1" 500 99789
ERROR 2024-08-19 19:18:17,424 log Internal Server Error: /api/nondb-candidates/
Traceback (most recent call last):
  File "C:\Users\LENOVO\AppData\Roaming\Python\Python312\site-packages\django\core\handlers\exception.py", line 55, in inner
    response = get_response(request)
               ^^^^^^^^^^^^^^^^^^^^^
  File "C:\Users\LENOVO\AppData\Roaming\Python\Python312\site-packages\django\core\handlers\base.py", line 197, in _get_response
    response = wrapped_callback(request, *callback_args, **callback_kwargs)
               ^^^^^^^^^^^^^^^^^^^^^^^^^^^^^^^^^^^^^^^^^^^^^^^^^^^^^^^^^^^^
  File "C:\Users\LENOVO\AppData\Roaming\Python\Python312\site-packages\django\views\decorators\csrf.py", line 65, in _view_wrapper
    return view_func(request, *args, **kwargs)
           ^^^^^^^^^^^^^^^^^^^^^^^^^^^^^^^^^^^
  File "C:\Users\LENOVO\AppData\Roaming\Python\Python312\site-packages\django\views\generic\base.py", line 104, in view
    return self.dispatch(request, *args, **kwargs)
           ^^^^^^^^^^^^^^^^^^^^^^^^^^^^^^^^^^^^^^^
  File "C:\Users\LENOVO\AppData\Roaming\Python\Python312\site-packages\rest_framework\views.py", line 509, in dispatch
    response = self.handle_exception(exc)
               ^^^^^^^^^^^^^^^^^^^^^^^^^^
  File "C:\Users\LENOVO\AppData\Roaming\Python\Python312\site-packages\rest_framework\views.py", line 469, in handle_exception
    self.raise_uncaught_exception(exc)
  File "C:\Users\LENOVO\AppData\Roaming\Python\Python312\site-packages\rest_framework\views.py", line 480, in raise_uncaught_exception
    raise exc
  File "C:\Users\LENOVO\AppData\Roaming\Python\Python312\site-packages\rest_framework\views.py", line 506, in dispatch
    response = handler(request, *args, **kwargs)
               ^^^^^^^^^^^^^^^^^^^^^^^^^^^^^^^^^
  File "C:\Users\LENOVO\AppData\Roaming\Python\Python312\site-packages\rest_framework\decorators.py", line 50, in handler
    return func(*args, **kwargs)
           ^^^^^^^^^^^^^^^^^^^^^
  File "D:\V_Project\LMS-New\backend\app\views.py", line 7526, in get_nondb_candidate
    nondatabase_candidates = login.objects.filter(
                             ^^^^^^^^^^^^^
AttributeError: 'function' object has no attribute 'objects'
ERROR 2024-08-19 19:18:17,555 basehttp "GET /api/nondb-candidates/ HTTP/1.1" 500 99789
ERROR 2024-08-19 19:18:18,246 log Internal Server Error: /api/nondb-candidates/
Traceback (most recent call last):
  File "C:\Users\LENOVO\AppData\Roaming\Python\Python312\site-packages\django\core\handlers\exception.py", line 55, in inner
    response = get_response(request)
               ^^^^^^^^^^^^^^^^^^^^^
  File "C:\Users\LENOVO\AppData\Roaming\Python\Python312\site-packages\django\core\handlers\base.py", line 197, in _get_response
    response = wrapped_callback(request, *callback_args, **callback_kwargs)
               ^^^^^^^^^^^^^^^^^^^^^^^^^^^^^^^^^^^^^^^^^^^^^^^^^^^^^^^^^^^^
  File "C:\Users\LENOVO\AppData\Roaming\Python\Python312\site-packages\django\views\decorators\csrf.py", line 65, in _view_wrapper
    return view_func(request, *args, **kwargs)
           ^^^^^^^^^^^^^^^^^^^^^^^^^^^^^^^^^^^
  File "C:\Users\LENOVO\AppData\Roaming\Python\Python312\site-packages\django\views\generic\base.py", line 104, in view
    return self.dispatch(request, *args, **kwargs)
           ^^^^^^^^^^^^^^^^^^^^^^^^^^^^^^^^^^^^^^^
  File "C:\Users\LENOVO\AppData\Roaming\Python\Python312\site-packages\rest_framework\views.py", line 509, in dispatch
    response = self.handle_exception(exc)
               ^^^^^^^^^^^^^^^^^^^^^^^^^^
  File "C:\Users\LENOVO\AppData\Roaming\Python\Python312\site-packages\rest_framework\views.py", line 469, in handle_exception
    self.raise_uncaught_exception(exc)
  File "C:\Users\LENOVO\AppData\Roaming\Python\Python312\site-packages\rest_framework\views.py", line 480, in raise_uncaught_exception
    raise exc
  File "C:\Users\LENOVO\AppData\Roaming\Python\Python312\site-packages\rest_framework\views.py", line 506, in dispatch
    response = handler(request, *args, **kwargs)
               ^^^^^^^^^^^^^^^^^^^^^^^^^^^^^^^^^
  File "C:\Users\LENOVO\AppData\Roaming\Python\Python312\site-packages\rest_framework\decorators.py", line 50, in handler
    return func(*args, **kwargs)
           ^^^^^^^^^^^^^^^^^^^^^
  File "D:\V_Project\LMS-New\backend\app\views.py", line 7526, in get_nondb_candidate
    nondatabase_candidates = login.objects.filter(
                             ^^^^^^^^^^^^^
AttributeError: 'function' object has no attribute 'objects'
ERROR 2024-08-19 19:18:18,574 basehttp "GET /api/nondb-candidates/ HTTP/1.1" 500 99789
ERROR 2024-08-19 19:27:31,915 log Internal Server Error: /api/nondb-candidates/
Traceback (most recent call last):
  File "C:\Users\LENOVO\AppData\Roaming\Python\Python312\site-packages\django\core\handlers\exception.py", line 55, in inner
    response = get_response(request)
               ^^^^^^^^^^^^^^^^^^^^^
  File "C:\Users\LENOVO\AppData\Roaming\Python\Python312\site-packages\django\core\handlers\base.py", line 197, in _get_response
    response = wrapped_callback(request, *callback_args, **callback_kwargs)
               ^^^^^^^^^^^^^^^^^^^^^^^^^^^^^^^^^^^^^^^^^^^^^^^^^^^^^^^^^^^^
  File "C:\Users\LENOVO\AppData\Roaming\Python\Python312\site-packages\django\views\decorators\csrf.py", line 65, in _view_wrapper
    return view_func(request, *args, **kwargs)
           ^^^^^^^^^^^^^^^^^^^^^^^^^^^^^^^^^^^
  File "C:\Users\LENOVO\AppData\Roaming\Python\Python312\site-packages\django\views\generic\base.py", line 104, in view
    return self.dispatch(request, *args, **kwargs)
           ^^^^^^^^^^^^^^^^^^^^^^^^^^^^^^^^^^^^^^^
  File "C:\Users\LENOVO\AppData\Roaming\Python\Python312\site-packages\rest_framework\views.py", line 509, in dispatch
    response = self.handle_exception(exc)
               ^^^^^^^^^^^^^^^^^^^^^^^^^^
  File "C:\Users\LENOVO\AppData\Roaming\Python\Python312\site-packages\rest_framework\views.py", line 469, in handle_exception
    self.raise_uncaught_exception(exc)
  File "C:\Users\LENOVO\AppData\Roaming\Python\Python312\site-packages\rest_framework\views.py", line 480, in raise_uncaught_exception
    raise exc
  File "C:\Users\LENOVO\AppData\Roaming\Python\Python312\site-packages\rest_framework\views.py", line 506, in dispatch
    response = handler(request, *args, **kwargs)
               ^^^^^^^^^^^^^^^^^^^^^^^^^^^^^^^^^
  File "C:\Users\LENOVO\AppData\Roaming\Python\Python312\site-packages\rest_framework\decorators.py", line 50, in handler
    return func(*args, **kwargs)
           ^^^^^^^^^^^^^^^^^^^^^
  File "D:\V_Project\LMS-New\backend\app\views.py", line 7533, in get_nondb_candidate
    nondatabase_candidates = login.objects.filter(
                             ^^^^^^^^^^^^^
AttributeError: 'function' object has no attribute 'objects'
ERROR 2024-08-19 19:27:32,148 basehttp "GET /api/nondb-candidates/ HTTP/1.1" 500 99789
ERROR 2024-08-19 19:27:34,948 log Internal Server Error: /api/nondb-candidates/
Traceback (most recent call last):
  File "C:\Users\LENOVO\AppData\Roaming\Python\Python312\site-packages\django\core\handlers\exception.py", line 55, in inner
    response = get_response(request)
               ^^^^^^^^^^^^^^^^^^^^^
  File "C:\Users\LENOVO\AppData\Roaming\Python\Python312\site-packages\django\core\handlers\base.py", line 197, in _get_response
    response = wrapped_callback(request, *callback_args, **callback_kwargs)
               ^^^^^^^^^^^^^^^^^^^^^^^^^^^^^^^^^^^^^^^^^^^^^^^^^^^^^^^^^^^^
  File "C:\Users\LENOVO\AppData\Roaming\Python\Python312\site-packages\django\views\decorators\csrf.py", line 65, in _view_wrapper
    return view_func(request, *args, **kwargs)
           ^^^^^^^^^^^^^^^^^^^^^^^^^^^^^^^^^^^
  File "C:\Users\LENOVO\AppData\Roaming\Python\Python312\site-packages\django\views\generic\base.py", line 104, in view
    return self.dispatch(request, *args, **kwargs)
           ^^^^^^^^^^^^^^^^^^^^^^^^^^^^^^^^^^^^^^^
  File "C:\Users\LENOVO\AppData\Roaming\Python\Python312\site-packages\rest_framework\views.py", line 509, in dispatch
    response = self.handle_exception(exc)
               ^^^^^^^^^^^^^^^^^^^^^^^^^^
  File "C:\Users\LENOVO\AppData\Roaming\Python\Python312\site-packages\rest_framework\views.py", line 469, in handle_exception
    self.raise_uncaught_exception(exc)
  File "C:\Users\LENOVO\AppData\Roaming\Python\Python312\site-packages\rest_framework\views.py", line 480, in raise_uncaught_exception
    raise exc
  File "C:\Users\LENOVO\AppData\Roaming\Python\Python312\site-packages\rest_framework\views.py", line 506, in dispatch
    response = handler(request, *args, **kwargs)
               ^^^^^^^^^^^^^^^^^^^^^^^^^^^^^^^^^
  File "C:\Users\LENOVO\AppData\Roaming\Python\Python312\site-packages\rest_framework\decorators.py", line 50, in handler
    return func(*args, **kwargs)
           ^^^^^^^^^^^^^^^^^^^^^
  File "D:\V_Project\LMS-New\backend\app\views.py", line 7533, in get_nondb_candidate
    nondatabase_candidates = login.objects.filter(
                             ^^^^^^^^^^^^^
AttributeError: 'function' object has no attribute 'objects'
ERROR 2024-08-19 19:27:35,291 basehttp "GET /api/nondb-candidates/ HTTP/1.1" 500 99789
ERROR 2024-08-19 19:38:07,567 log Internal Server Error: /api/get_candidate_login/
Traceback (most recent call last):
  File "C:\Users\LENOVO\AppData\Roaming\Python\Python312\site-packages\django\core\handlers\exception.py", line 55, in inner
    response = get_response(request)
               ^^^^^^^^^^^^^^^^^^^^^
  File "C:\Users\LENOVO\AppData\Roaming\Python\Python312\site-packages\django\core\handlers\base.py", line 197, in _get_response
    response = wrapped_callback(request, *callback_args, **callback_kwargs)
               ^^^^^^^^^^^^^^^^^^^^^^^^^^^^^^^^^^^^^^^^^^^^^^^^^^^^^^^^^^^^
  File "C:\Users\LENOVO\AppData\Roaming\Python\Python312\site-packages\django\views\decorators\csrf.py", line 65, in _view_wrapper
    return view_func(request, *args, **kwargs)
           ^^^^^^^^^^^^^^^^^^^^^^^^^^^^^^^^^^^
  File "C:\Users\LENOVO\AppData\Roaming\Python\Python312\site-packages\django\views\generic\base.py", line 104, in view
    return self.dispatch(request, *args, **kwargs)
           ^^^^^^^^^^^^^^^^^^^^^^^^^^^^^^^^^^^^^^^
  File "C:\Users\LENOVO\AppData\Roaming\Python\Python312\site-packages\rest_framework\views.py", line 509, in dispatch
    response = self.handle_exception(exc)
               ^^^^^^^^^^^^^^^^^^^^^^^^^^
  File "C:\Users\LENOVO\AppData\Roaming\Python\Python312\site-packages\rest_framework\views.py", line 469, in handle_exception
    self.raise_uncaught_exception(exc)
  File "C:\Users\LENOVO\AppData\Roaming\Python\Python312\site-packages\rest_framework\views.py", line 480, in raise_uncaught_exception
    raise exc
  File "C:\Users\LENOVO\AppData\Roaming\Python\Python312\site-packages\rest_framework\views.py", line 506, in dispatch
    response = handler(request, *args, **kwargs)
               ^^^^^^^^^^^^^^^^^^^^^^^^^^^^^^^^^
  File "C:\Users\LENOVO\AppData\Roaming\Python\Python312\site-packages\rest_framework\decorators.py", line 50, in handler
    return func(*args, **kwargs)
           ^^^^^^^^^^^^^^^^^^^^^
  File "D:\V_Project\LMS-New\backend\app\views.py", line 3802, in get_candidate_login
    login_subquery = login.objects.filter(user_name=OuterRef('user_name')).values('password')[:1]
                     ^^^^^^^^^^^^^
AttributeError: 'function' object has no attribute 'objects'
ERROR 2024-08-19 19:38:07,814 basehttp "GET /api/get_candidate_login/ HTTP/1.1" 500 100323
ERROR 2024-08-19 20:01:24,157 log Internal Server Error: /api/nondb-candidates/
Traceback (most recent call last):
  File "C:\Users\LENOVO\AppData\Roaming\Python\Python312\site-packages\django\core\handlers\exception.py", line 55, in inner
    response = get_response(request)
               ^^^^^^^^^^^^^^^^^^^^^
  File "C:\Users\LENOVO\AppData\Roaming\Python\Python312\site-packages\django\core\handlers\base.py", line 197, in _get_response
    response = wrapped_callback(request, *callback_args, **callback_kwargs)
               ^^^^^^^^^^^^^^^^^^^^^^^^^^^^^^^^^^^^^^^^^^^^^^^^^^^^^^^^^^^^
  File "C:\Users\LENOVO\AppData\Roaming\Python\Python312\site-packages\django\views\decorators\csrf.py", line 65, in _view_wrapper
    return view_func(request, *args, **kwargs)
           ^^^^^^^^^^^^^^^^^^^^^^^^^^^^^^^^^^^
  File "C:\Users\LENOVO\AppData\Roaming\Python\Python312\site-packages\django\views\generic\base.py", line 104, in view
    return self.dispatch(request, *args, **kwargs)
           ^^^^^^^^^^^^^^^^^^^^^^^^^^^^^^^^^^^^^^^
  File "C:\Users\LENOVO\AppData\Roaming\Python\Python312\site-packages\rest_framework\views.py", line 509, in dispatch
    response = self.handle_exception(exc)
               ^^^^^^^^^^^^^^^^^^^^^^^^^^
  File "C:\Users\LENOVO\AppData\Roaming\Python\Python312\site-packages\rest_framework\views.py", line 469, in handle_exception
    self.raise_uncaught_exception(exc)
  File "C:\Users\LENOVO\AppData\Roaming\Python\Python312\site-packages\rest_framework\views.py", line 480, in raise_uncaught_exception
    raise exc
  File "C:\Users\LENOVO\AppData\Roaming\Python\Python312\site-packages\rest_framework\views.py", line 506, in dispatch
    response = handler(request, *args, **kwargs)
               ^^^^^^^^^^^^^^^^^^^^^^^^^^^^^^^^^
  File "C:\Users\LENOVO\AppData\Roaming\Python\Python312\site-packages\rest_framework\decorators.py", line 50, in handler
    return func(*args, **kwargs)
           ^^^^^^^^^^^^^^^^^^^^^
  File "D:\V_Project\LMS-New\backend\app\views.py", line 7535, in get_nondb_candidate
    nondatabase_candidates = login.objects.filter(
                             ^^^^^^^^^^^^^
AttributeError: 'function' object has no attribute 'objects'
ERROR 2024-08-19 20:01:24,375 basehttp "GET /api/nondb-candidates/ HTTP/1.1" 500 100624
ERROR 2024-08-19 21:57:07,657 views Catch Key...: question_data_code_5
ERROR 2024-08-19 21:57:08,057 views -----Data From Cache----
ERROR 2024-08-19 21:57:08,310 views -----Data From Database----
ERROR 2024-08-19 22:11:50,099 views Catch Key...: question_data_code_5
ERROR 2024-08-19 22:11:50,917 views -----Data From Cache----
ERROR 2024-08-19 22:11:51,355 views -----Data From Database----
ERROR 2024-08-19 22:22:32,647 views Catch Key...: question_data_code_5
ERROR 2024-08-19 22:22:32,765 views -----Data From Cache----
ERROR 2024-08-19 22:33:14,636 views Catch Key...: question_data_code_5
ERROR 2024-08-19 22:33:14,641 views -----Data From Cache----
ERROR 2024-08-19 22:51:11,010 views Catch Key...: question_data_code_21
ERROR 2024-08-19 22:51:11,144 views -----Data From Cache----
ERROR 2024-08-19 22:51:11,205 views -----Data From Database----
ERROR 2024-08-19 23:54:28,021 log Internal Server Error: /api/update/clg_login/Name102/
Traceback (most recent call last):
  File "C:\Users\LENOVO\AppData\Roaming\Python\Python312\site-packages\django\core\handlers\exception.py", line 55, in inner
    response = get_response(request)
               ^^^^^^^^^^^^^^^^^^^^^
  File "C:\Users\LENOVO\AppData\Roaming\Python\Python312\site-packages\django\core\handlers\base.py", line 197, in _get_response
    response = wrapped_callback(request, *callback_args, **callback_kwargs)
               ^^^^^^^^^^^^^^^^^^^^^^^^^^^^^^^^^^^^^^^^^^^^^^^^^^^^^^^^^^^^
  File "C:\Users\LENOVO\AppData\Roaming\Python\Python312\site-packages\django\views\decorators\csrf.py", line 65, in _view_wrapper
    return view_func(request, *args, **kwargs)
           ^^^^^^^^^^^^^^^^^^^^^^^^^^^^^^^^^^^
  File "C:\Users\LENOVO\AppData\Roaming\Python\Python312\site-packages\django\views\generic\base.py", line 104, in view
    return self.dispatch(request, *args, **kwargs)
           ^^^^^^^^^^^^^^^^^^^^^^^^^^^^^^^^^^^^^^^
  File "C:\Users\LENOVO\AppData\Roaming\Python\Python312\site-packages\rest_framework\views.py", line 509, in dispatch
    response = self.handle_exception(exc)
               ^^^^^^^^^^^^^^^^^^^^^^^^^^
  File "C:\Users\LENOVO\AppData\Roaming\Python\Python312\site-packages\rest_framework\views.py", line 469, in handle_exception
    self.raise_uncaught_exception(exc)
  File "C:\Users\LENOVO\AppData\Roaming\Python\Python312\site-packages\rest_framework\views.py", line 480, in raise_uncaught_exception
    raise exc
  File "C:\Users\LENOVO\AppData\Roaming\Python\Python312\site-packages\rest_framework\views.py", line 506, in dispatch
    response = handler(request, *args, **kwargs)
               ^^^^^^^^^^^^^^^^^^^^^^^^^^^^^^^^^
  File "C:\Users\LENOVO\AppData\Roaming\Python\Python312\site-packages\rest_framework\decorators.py", line 50, in handler
    return func(*args, **kwargs)
           ^^^^^^^^^^^^^^^^^^^^^
  File "D:\V_Project\LMS-New\backend\app\views.py", line 3731, in update_clg_login
    serializer.save()
  File "C:\Users\LENOVO\AppData\Roaming\Python\Python312\site-packages\rest_framework\serializers.py", line 203, in save
    self.instance = self.update(self.instance, validated_data)
                    ^^^^^^^^^^^^^^^^^^^^^^^^^^^^^^^^^^^^^^^^^^
  File "D:\V_Project\LMS-New\backend\app\serializers.py", line 624, in update
    user_data = validated_data.pop('user')
                ^^^^^^^^^^^^^^^^^^^^^^^^^^
KeyError: 'user'
ERROR 2024-08-19 23:54:28,337 basehttp "PUT /api/update/clg_login/Name102/ HTTP/1.1" 500 111592
ERROR 2024-08-20 00:09:34,957 views Catch Key...: question_data_code_21
ERROR 2024-08-20 00:09:35,540 views -----Data From Cache----
ERROR 2024-08-20 00:09:35,699 views -----Data From Database----
ERROR 2024-08-20 12:30:59,896 views Catch Key...: question_data_code_22
ERROR 2024-08-20 12:31:00,113 views -----Data From Cache----
ERROR 2024-08-20 12:31:00,687 views -----Data From Database----
ERROR 2024-08-20 12:43:24,102 views Catch Key...: question_data_code_22
ERROR 2024-08-20 12:43:24,167 views -----Data From Cache----
ERROR 2024-08-20 15:17:49,949 views Catch Key...: question_data_code_22
ERROR 2024-08-20 15:17:50,853 views -----Data From Cache----
ERROR 2024-08-20 15:17:51,330 views -----Data From Database----
ERROR 2024-08-20 15:20:47,150 views Catch Key...: question_data_code_22
ERROR 2024-08-20 15:20:47,158 views -----Data From Cache----
ERROR 2024-08-20 17:29:38,151 views Catch Key...: question_data_code_22
ERROR 2024-08-20 17:29:38,316 views -----Data From Cache----
ERROR 2024-08-20 17:29:38,482 views -----Data From Database----
ERROR 2024-08-20 17:54:04,109 views Catch Key...: question_data_code_22
ERROR 2024-08-20 17:54:04,765 views -----Data From Cache----
ERROR 2024-08-20 17:54:06,454 views -----Data From Database----
ERROR 2024-08-20 22:26:31,906 views Catch Key...: question_data_code_22
ERROR 2024-08-20 22:26:32,681 views -----Data From Cache----
ERROR 2024-08-20 22:26:33,892 views -----Data From Database----
ERROR 2024-08-20 22:27:20,363 log Internal Server Error: /api/tests-answer-com/
ERROR 2024-08-20 22:27:20,365 basehttp "POST /api/tests-answer-com/ HTTP/1.1" 500 104
ERROR 2024-08-20 22:29:43,520 log Internal Server Error: /api/tests-answer-com/
ERROR 2024-08-20 22:29:43,523 basehttp "POST /api/tests-answer-com/ HTTP/1.1" 500 104
ERROR 2024-08-20 22:35:48,463 log Internal Server Error: /api/tests-answer-com/
ERROR 2024-08-20 22:35:48,466 basehttp "POST /api/tests-answer-com/ HTTP/1.1" 500 104
ERROR 2024-08-20 22:45:05,005 log Internal Server Error: /api/tests-answer-com/
ERROR 2024-08-20 22:45:05,008 basehttp "POST /api/tests-answer-com/ HTTP/1.1" 500 104
ERROR 2024-08-20 23:02:56,497 log Internal Server Error: /api/tests-answer-com/
ERROR 2024-08-20 23:02:56,499 basehttp "POST /api/tests-answer-com/ HTTP/1.1" 500 60
ERROR 2024-08-20 23:07:55,396 log Internal Server Error: /api/tests-answer-com/
ERROR 2024-08-20 23:07:55,448 basehttp "POST /api/tests-answer-com/ HTTP/1.1" 500 60
ERROR 2024-08-20 23:14:46,855 views Catch Key...: question_data_code_22
ERROR 2024-08-20 23:14:47,164 views -----Data From Cache----
ERROR 2024-08-20 23:14:47,709 views -----Data From Database----
ERROR 2024-08-20 23:15:28,988 log Internal Server Error: /api/tests-answer-com/
ERROR 2024-08-20 23:15:28,994 basehttp "POST /api/tests-answer-com/ HTTP/1.1" 500 60
ERROR 2024-08-20 23:19:02,049 log Internal Server Error: /api/tests-answer-com/
ERROR 2024-08-20 23:19:02,058 basehttp "POST /api/tests-answer-com/ HTTP/1.1" 500 60
ERROR 2024-08-20 23:21:24,085 log Internal Server Error: /api/tests-answer-com/
ERROR 2024-08-20 23:21:24,096 basehttp "POST /api/tests-answer-com/ HTTP/1.1" 500 60
