ERROR 2024-08-21 11:13:53,877 views Catch Key...: question_data_code_22
ERROR 2024-08-21 11:14:00,284 views -----Data From Cache----
ERROR 2024-08-21 11:14:13,202 views -----Data From Database----
ERROR 2024-08-21 11:33:54,721 views Catch Key...: question_data_code_22
ERROR 2024-08-21 11:33:55,996 views -----Data From Cache----
ERROR 2024-08-21 11:56:05,789 views Catch Key...: question_data_code_22
ERROR 2024-08-21 11:56:07,533 views -----Data From Cache----
ERROR 2024-08-21 15:40:39,855 log Internal Server Error: /api/update-is-accept/5/
Traceback (most recent call last):
  File "C:\Users\LENOVO\AppData\Roaming\Python\Python312\site-packages\django\core\handlers\exception.py", line 55, in inner
    response = get_response(request)
               ^^^^^^^^^^^^^^^^^^^^^
  File "C:\Users\LENOVO\AppData\Roaming\Python\Python312\site-packages\django\core\handlers\base.py", line 197, in _get_response
    response = wrapped_callback(request, *callback_args, **callback_kwargs)
               ^^^^^^^^^^^^^^^^^^^^^^^^^^^^^^^^^^^^^^^^^^^^^^^^^^^^^^^^^^^^
  File "C:\Users\LENOVO\AppData\Roaming\Python\Python312\site-packages\django\views\decorators\csrf.py", line 65, in _view_wrapper
    return view_func(request, *args, **kwargs)
           ^^^^^^^^^^^^^^^^^^^^^^^^^^^^^^^^^^^
  File "C:\Users\LENOVO\AppData\Roaming\Python\Python312\site-packages\django\views\generic\base.py", line 104, in view
    return self.dispatch(request, *args, **kwargs)
           ^^^^^^^^^^^^^^^^^^^^^^^^^^^^^^^^^^^^^^^
  File "C:\Users\LENOVO\AppData\Roaming\Python\Python312\site-packages\rest_framework\views.py", line 509, in dispatch
    response = self.handle_exception(exc)
               ^^^^^^^^^^^^^^^^^^^^^^^^^^
  File "C:\Users\LENOVO\AppData\Roaming\Python\Python312\site-packages\rest_framework\views.py", line 469, in handle_exception
    self.raise_uncaught_exception(exc)
  File "C:\Users\LENOVO\AppData\Roaming\Python\Python312\site-packages\rest_framework\views.py", line 480, in raise_uncaught_exception
    raise exc
  File "C:\Users\LENOVO\AppData\Roaming\Python\Python312\site-packages\rest_framework\views.py", line 506, in dispatch
    response = handler(request, *args, **kwargs)
               ^^^^^^^^^^^^^^^^^^^^^^^^^^^^^^^^^
  File "C:\Users\LENOVO\AppData\Roaming\Python\Python312\site-packages\rest_framework\decorators.py", line 50, in handler
    return func(*args, **kwargs)
           ^^^^^^^^^^^^^^^^^^^^^
  File "D:\V_Project\LMS-New\backend\app\views.py", line 7630, in update_is_accept
    candidate.round_of_interview = 'Registered'
    ^^^^^^^^^
NameError: name 'candidate' is not defined. Did you mean: 'candidates'?
ERROR 2024-08-21 15:40:39,979 basehttp "PATCH /api/update-is-accept/5/ HTTP/1.1" 500 99815
ERROR 2024-08-22 12:44:19,340 log Internal Server Error: /api/course-content/Trainer/
ERROR 2024-08-22 12:44:19,847 basehttp "GET /api/course-content/Trainer/?user_name=trainer31 HTTP/1.1" 500 54
ERROR 2024-08-22 12:44:20,807 log Internal Server Error: /api/course-content/Trainer/
ERROR 2024-08-22 12:44:20,875 basehttp "GET /api/course-content/Trainer/?user_name=trainer31 HTTP/1.1" 500 54
ERROR 2024-08-22 19:30:41,849 log Internal Server Error: /api/course-content/Trainer/
ERROR 2024-08-22 19:30:42,205 basehttp "GET /api/course-content/Trainer/?user_name=trainer31 HTTP/1.1" 500 54
ERROR 2024-08-22 19:30:42,562 log Internal Server Error: /api/course-content/Trainer/
ERROR 2024-08-22 19:30:42,565 basehttp "GET /api/course-content/Trainer/?user_name=trainer31 HTTP/1.1" 500 54
ERROR 2024-08-23 00:30:48,480 log Internal Server Error: /api/round-of-interview-count/
ERROR 2024-08-23 00:30:48,579 basehttp "GET /api/round-of-interview-count/?college_id=1&company_name=Wipro HTTP/1.1" 500 5894
ERROR 2024-08-23 13:14:52,590 log Internal Server Error: /api/trainers/all/
ERROR 2024-08-23 13:14:52,998 basehttp "GET /api/trainers/all/ HTTP/1.1" 500 67
ERROR 2024-08-23 13:14:54,697 log Internal Server Error: /api/trainers/all/
ERROR 2024-08-23 13:14:54,703 basehttp "GET /api/trainers/all/ HTTP/1.1" 500 67
ERROR 2024-08-23 13:38:38,076 log Internal Server Error: /api/trainers/all/
ERROR 2024-08-23 13:38:38,452 basehttp "GET /api/trainers/all/ HTTP/1.1" 500 67
ERROR 2024-08-23 13:38:38,758 log Internal Server Error: /api/trainers/all/
ERROR 2024-08-23 13:38:38,761 basehttp "GET /api/trainers/all/ HTTP/1.1" 500 67
ERROR 2024-08-23 13:40:47,465 log Internal Server Error: /api/trainers/all/
ERROR 2024-08-23 13:40:47,589 basehttp "GET /api/trainers/all/ HTTP/1.1" 500 5334
ERROR 2024-08-23 19:30:21,812 log Internal Server Error: /api/upload-screenshot/116
Traceback (most recent call last):
  File "C:\Users\LENOVO\AppData\Roaming\Python\Python312\site-packages\django\core\handlers\exception.py", line 55, in inner
    response = get_response(request)
               ^^^^^^^^^^^^^^^^^^^^^
  File "C:\Users\LENOVO\AppData\Roaming\Python\Python312\site-packages\django\utils\deprecation.py", line 136, in __call__
    response = self.process_response(request, response)
               ^^^^^^^^^^^^^^^^^^^^^^^^^^^^^^^^^^^^^^^^
  File "C:\Users\LENOVO\AppData\Roaming\Python\Python312\site-packages\django\middleware\common.py", line 108, in process_response
    return self.response_redirect_class(self.get_full_path_with_slash(request))
                                        ^^^^^^^^^^^^^^^^^^^^^^^^^^^^^^^^^^^^^^
  File "C:\Users\LENOVO\AppData\Roaming\Python\Python312\site-packages\django\middleware\common.py", line 87, in get_full_path_with_slash
    raise RuntimeError(
RuntimeError: You called this URL via POST, but the URL doesn't end in a slash and you have APPEND_SLASH set. Django can't redirect to the slash URL while maintaining POST data. Change your form to point to localhost:8000/api/upload-screenshot/116/ (note the trailing slash), or set APPEND_SLASH=False in your Django settings.
ERROR 2024-08-23 19:30:21,990 basehttp "POST /api/upload-screenshot/116 HTTP/1.1" 500 73742
ERROR 2024-08-23 19:31:10,902 log Internal Server Error: /api/upload-screenshot/116
Traceback (most recent call last):
  File "C:\Users\LENOVO\AppData\Roaming\Python\Python312\site-packages\django\core\handlers\exception.py", line 55, in inner
    response = get_response(request)
               ^^^^^^^^^^^^^^^^^^^^^
  File "C:\Users\LENOVO\AppData\Roaming\Python\Python312\site-packages\django\utils\deprecation.py", line 136, in __call__
    response = self.process_response(request, response)
               ^^^^^^^^^^^^^^^^^^^^^^^^^^^^^^^^^^^^^^^^
  File "C:\Users\LENOVO\AppData\Roaming\Python\Python312\site-packages\django\middleware\common.py", line 108, in process_response
    return self.response_redirect_class(self.get_full_path_with_slash(request))
                                        ^^^^^^^^^^^^^^^^^^^^^^^^^^^^^^^^^^^^^^
  File "C:\Users\LENOVO\AppData\Roaming\Python\Python312\site-packages\django\middleware\common.py", line 87, in get_full_path_with_slash
    raise RuntimeError(
RuntimeError: You called this URL via POST, but the URL doesn't end in a slash and you have APPEND_SLASH set. Django can't redirect to the slash URL while maintaining POST data. Change your form to point to localhost:8000/api/upload-screenshot/116/ (note the trailing slash), or set APPEND_SLASH=False in your Django settings.
ERROR 2024-08-23 19:31:11,702 basehttp "POST /api/upload-screenshot/116 HTTP/1.1" 500 73742
ERROR 2024-08-23 19:33:35,527 log Internal Server Error: /api/upload-screenshot/116/
Traceback (most recent call last):
  File "C:\Users\LENOVO\AppData\Roaming\Python\Python312\site-packages\django\core\handlers\exception.py", line 55, in inner
    response = get_response(request)
               ^^^^^^^^^^^^^^^^^^^^^
  File "C:\Users\LENOVO\AppData\Roaming\Python\Python312\site-packages\django\core\handlers\base.py", line 197, in _get_response
    response = wrapped_callback(request, *callback_args, **callback_kwargs)
               ^^^^^^^^^^^^^^^^^^^^^^^^^^^^^^^^^^^^^^^^^^^^^^^^^^^^^^^^^^^^
  File "C:\Users\LENOVO\AppData\Roaming\Python\Python312\site-packages\django\views\decorators\csrf.py", line 65, in _view_wrapper
    return view_func(request, *args, **kwargs)
           ^^^^^^^^^^^^^^^^^^^^^^^^^^^^^^^^^^^
  File "D:\V_Project\LMS-New\backend\app\views.py", line 8201, in upload_screenshot
    instance.test_candidate_id = pk
    ^^^^^^^^^^^^^^^^^^^^^^^^^^
  File "C:\Users\LENOVO\AppData\Roaming\Python\Python312\site-packages\django\db\models\fields\related_descriptors.py", line 284, in __set__
    raise ValueError(
ValueError: Cannot assign "116": "Screenshots.test_candidate_id" must be a "tests_candidates_map" instance.
ERROR 2024-08-23 19:33:35,669 basehttp "POST /api/upload-screenshot/116/ HTTP/1.1" 500 77681
ERROR 2024-08-23 19:34:25,684 log Internal Server Error: /api/upload-screenshot/116/
Traceback (most recent call last):
  File "C:\Users\LENOVO\AppData\Roaming\Python\Python312\site-packages\django\core\handlers\exception.py", line 55, in inner
    response = get_response(request)
               ^^^^^^^^^^^^^^^^^^^^^
  File "C:\Users\LENOVO\AppData\Roaming\Python\Python312\site-packages\django\core\handlers\base.py", line 197, in _get_response
    response = wrapped_callback(request, *callback_args, **callback_kwargs)
               ^^^^^^^^^^^^^^^^^^^^^^^^^^^^^^^^^^^^^^^^^^^^^^^^^^^^^^^^^^^^
  File "C:\Users\LENOVO\AppData\Roaming\Python\Python312\site-packages\django\views\decorators\csrf.py", line 65, in _view_wrapper
    return view_func(request, *args, **kwargs)
           ^^^^^^^^^^^^^^^^^^^^^^^^^^^^^^^^^^^
  File "D:\V_Project\LMS-New\backend\app\views.py", line 8201, in upload_screenshot
    instance.test_candidate_id = pk
    ^^^^^^^^^^^^^^^^^^^^^^^^^^
  File "C:\Users\LENOVO\AppData\Roaming\Python\Python312\site-packages\django\db\models\fields\related_descriptors.py", line 284, in __set__
    raise ValueError(
ValueError: Cannot assign "116": "Screenshots.test_candidate_id" must be a "tests_candidates_map" instance.
ERROR 2024-08-23 19:34:25,918 basehttp "POST /api/upload-screenshot/116/ HTTP/1.1" 500 77681
ERROR 2024-08-23 19:35:15,400 log Internal Server Error: /api/upload-screenshot/116/
Traceback (most recent call last):
  File "C:\Users\LENOVO\AppData\Roaming\Python\Python312\site-packages\django\core\handlers\exception.py", line 55, in inner
    response = get_response(request)
               ^^^^^^^^^^^^^^^^^^^^^
  File "C:\Users\LENOVO\AppData\Roaming\Python\Python312\site-packages\django\core\handlers\base.py", line 197, in _get_response
    response = wrapped_callback(request, *callback_args, **callback_kwargs)
               ^^^^^^^^^^^^^^^^^^^^^^^^^^^^^^^^^^^^^^^^^^^^^^^^^^^^^^^^^^^^
  File "C:\Users\LENOVO\AppData\Roaming\Python\Python312\site-packages\django\views\decorators\csrf.py", line 65, in _view_wrapper
    return view_func(request, *args, **kwargs)
           ^^^^^^^^^^^^^^^^^^^^^^^^^^^^^^^^^^^
  File "D:\V_Project\LMS-New\backend\app\views.py", line 8201, in upload_screenshot
    instance.test_candidate_id = pk
    ^^^^^^^^^^^^^^^^^^^^^^^^^^
  File "C:\Users\LENOVO\AppData\Roaming\Python\Python312\site-packages\django\db\models\fields\related_descriptors.py", line 284, in __set__
    raise ValueError(
ValueError: Cannot assign "116": "Screenshots.test_candidate_id" must be a "tests_candidates_map" instance.
ERROR 2024-08-23 19:35:15,427 basehttp "POST /api/upload-screenshot/116/ HTTP/1.1" 500 77681
ERROR 2024-08-23 22:04:47,375 log Internal Server Error: /api//students/announcement/2/
Traceback (most recent call last):
  File "C:\Users\LENOVO\AppData\Roaming\Python\Python312\site-packages\django\core\handlers\exception.py", line 55, in inner
    response = get_response(request)
               ^^^^^^^^^^^^^^^^^^^^^
  File "C:\Users\LENOVO\AppData\Roaming\Python\Python312\site-packages\django\core\handlers\base.py", line 197, in _get_response
    response = wrapped_callback(request, *callback_args, **callback_kwargs)
               ^^^^^^^^^^^^^^^^^^^^^^^^^^^^^^^^^^^^^^^^^^^^^^^^^^^^^^^^^^^^
  File "C:\Users\LENOVO\AppData\Roaming\Python\Python312\site-packages\django\views\decorators\csrf.py", line 65, in _view_wrapper
    return view_func(request, *args, **kwargs)
           ^^^^^^^^^^^^^^^^^^^^^^^^^^^^^^^^^^^
  File "C:\Users\LENOVO\AppData\Roaming\Python\Python312\site-packages\django\views\generic\base.py", line 104, in view
    return self.dispatch(request, *args, **kwargs)
           ^^^^^^^^^^^^^^^^^^^^^^^^^^^^^^^^^^^^^^^
  File "C:\Users\LENOVO\AppData\Roaming\Python\Python312\site-packages\rest_framework\views.py", line 509, in dispatch
    response = self.handle_exception(exc)
               ^^^^^^^^^^^^^^^^^^^^^^^^^^
  File "C:\Users\LENOVO\AppData\Roaming\Python\Python312\site-packages\rest_framework\views.py", line 469, in handle_exception
    self.raise_uncaught_exception(exc)
  File "C:\Users\LENOVO\AppData\Roaming\Python\Python312\site-packages\rest_framework\views.py", line 480, in raise_uncaught_exception
    raise exc
  File "C:\Users\LENOVO\AppData\Roaming\Python\Python312\site-packages\rest_framework\views.py", line 506, in dispatch
    response = handler(request, *args, **kwargs)
               ^^^^^^^^^^^^^^^^^^^^^^^^^^^^^^^^^
  File "C:\Users\LENOVO\AppData\Roaming\Python\Python312\site-packages\rest_framework\decorators.py", line 50, in handler
    return func(*args, **kwargs)
           ^^^^^^^^^^^^^^^^^^^^^
  File "D:\V_Project\LMS-New\backend\app\views.py", line 8225, in get_student_announcement
    'announcement_image': student_entry.announcement_image.decode('utf-8') if student_entry.announcement_image else None
                          ^^^^^^^^^^^^^^^^^^^^^^^^^^^^^^^^^^^^^^^
AttributeError: 'memoryview' object has no attribute 'decode'
ERROR 2024-08-23 22:04:47,516 basehttp "GET /api//students/announcement/2/ HTTP/1.1" 500 100760
ERROR 2024-08-23 23:23:57,643 log Internal Server Error: /api//students/announcement/2/
Traceback (most recent call last):
  File "C:\Users\LENOVO\AppData\Roaming\Python\Python312\site-packages\django\core\handlers\exception.py", line 55, in inner
    response = get_response(request)
               ^^^^^^^^^^^^^^^^^^^^^
  File "C:\Users\LENOVO\AppData\Roaming\Python\Python312\site-packages\django\core\handlers\base.py", line 197, in _get_response
    response = wrapped_callback(request, *callback_args, **callback_kwargs)
               ^^^^^^^^^^^^^^^^^^^^^^^^^^^^^^^^^^^^^^^^^^^^^^^^^^^^^^^^^^^^
  File "C:\Users\LENOVO\AppData\Roaming\Python\Python312\site-packages\django\views\decorators\csrf.py", line 65, in _view_wrapper
    return view_func(request, *args, **kwargs)
           ^^^^^^^^^^^^^^^^^^^^^^^^^^^^^^^^^^^
  File "C:\Users\LENOVO\AppData\Roaming\Python\Python312\site-packages\django\views\generic\base.py", line 104, in view
    return self.dispatch(request, *args, **kwargs)
           ^^^^^^^^^^^^^^^^^^^^^^^^^^^^^^^^^^^^^^^
  File "C:\Users\LENOVO\AppData\Roaming\Python\Python312\site-packages\rest_framework\views.py", line 509, in dispatch
    response = self.handle_exception(exc)
               ^^^^^^^^^^^^^^^^^^^^^^^^^^
  File "C:\Users\LENOVO\AppData\Roaming\Python\Python312\site-packages\rest_framework\views.py", line 469, in handle_exception
    self.raise_uncaught_exception(exc)
  File "C:\Users\LENOVO\AppData\Roaming\Python\Python312\site-packages\rest_framework\views.py", line 480, in raise_uncaught_exception
    raise exc
  File "C:\Users\LENOVO\AppData\Roaming\Python\Python312\site-packages\rest_framework\views.py", line 506, in dispatch
    response = handler(request, *args, **kwargs)
               ^^^^^^^^^^^^^^^^^^^^^^^^^^^^^^^^^
  File "C:\Users\LENOVO\AppData\Roaming\Python\Python312\site-packages\rest_framework\decorators.py", line 50, in handler
    return func(*args, **kwargs)
           ^^^^^^^^^^^^^^^^^^^^^
  File "D:\V_Project\LMS-New\backend\app\views.py", line 8223, in get_student_announcement
    data = list(map(lambda entry: {
                ^^^^^^^^^^^^^^^^^^^
TypeError: 'eligible_student_list' object is not iterable
ERROR 2024-08-23 23:23:58,014 basehttp "GET /api//students/announcement/2/ HTTP/1.1" 500 100506
ERROR 2024-08-24 12:01:52,165 log Internal Server Error: /api/trainers/all/
ERROR 2024-08-24 12:01:53,409 basehttp "GET /api/trainers/all/ HTTP/1.1" 500 213
ERROR 2024-08-24 12:01:54,590 log Internal Server Error: /api/trainers/all/
ERROR 2024-08-24 12:01:55,944 basehttp "GET /api/trainers/all/ HTTP/1.1" 500 213
ERROR 2024-08-24 12:02:26,660 log Internal Server Error: /api/course-content/Trainer/
ERROR 2024-08-24 12:02:26,680 basehttp "GET /api/course-content/Trainer/?user_name=Trainer100 HTTP/1.1" 500 5757
ERROR 2024-08-24 17:39:43,431 views Error occurred in get_login function: 'function' object has no attribute 'objects'
ERROR 2024-08-24 17:39:43,443 log Internal Server Error: /api/get/login/
ERROR 2024-08-24 17:39:43,446 basehttp "GET /api/get/login/ HTTP/1.1" 500 29
ERROR 2024-08-24 17:40:14,912 views Error occurred in get_login function: 'function' object has no attribute 'objects'
ERROR 2024-08-24 17:40:14,918 log Internal Server Error: /api/get/login/
ERROR 2024-08-24 17:40:14,922 basehttp "GET /api/get/login/ HTTP/1.1" 500 29
ERROR 2024-08-24 17:40:38,045 views Error occurred in get_login function: 'function' object has no attribute 'objects'
ERROR 2024-08-24 17:40:38,565 log Internal Server Error: /api/get/login/
ERROR 2024-08-24 17:40:38,586 basehttp "GET /api/get/login/ HTTP/1.1" 500 5216
ERROR 2024-08-24 17:43:31,434 views Error occurred in get_login function: 'function' object has no attribute 'objects'
ERROR 2024-08-24 17:43:31,864 log Internal Server Error: /api/get/login/
ERROR 2024-08-24 17:43:31,882 basehttp "GET /api/get/login/ HTTP/1.1" 500 5216
ERROR 2024-08-24 17:45:11,831 views Error occurred in get_login function: 'function' object has no attribute 'objects'
ERROR 2024-08-24 17:45:12,047 log Internal Server Error: /api/get/login/
ERROR 2024-08-24 17:45:12,058 basehttp "GET /api/get/login/ HTTP/1.1" 500 5216
ERROR 2024-08-24 18:33:30,319 log Internal Server Error: /api/nondb-candidates/
Traceback (most recent call last):
  File "C:\Users\LENOVO\AppData\Roaming\Python\Python312\site-packages\django\core\handlers\exception.py", line 55, in inner
    response = get_response(request)
               ^^^^^^^^^^^^^^^^^^^^^
  File "C:\Users\LENOVO\AppData\Roaming\Python\Python312\site-packages\django\core\handlers\base.py", line 197, in _get_response
    response = wrapped_callback(request, *callback_args, **callback_kwargs)
               ^^^^^^^^^^^^^^^^^^^^^^^^^^^^^^^^^^^^^^^^^^^^^^^^^^^^^^^^^^^^
  File "C:\Users\LENOVO\AppData\Roaming\Python\Python312\site-packages\django\views\decorators\csrf.py", line 65, in _view_wrapper
    return view_func(request, *args, **kwargs)
           ^^^^^^^^^^^^^^^^^^^^^^^^^^^^^^^^^^^
  File "C:\Users\LENOVO\AppData\Roaming\Python\Python312\site-packages\django\views\generic\base.py", line 104, in view
    return self.dispatch(request, *args, **kwargs)
           ^^^^^^^^^^^^^^^^^^^^^^^^^^^^^^^^^^^^^^^
  File "C:\Users\LENOVO\AppData\Roaming\Python\Python312\site-packages\rest_framework\views.py", line 509, in dispatch
    response = self.handle_exception(exc)
               ^^^^^^^^^^^^^^^^^^^^^^^^^^
  File "C:\Users\LENOVO\AppData\Roaming\Python\Python312\site-packages\rest_framework\views.py", line 469, in handle_exception
    self.raise_uncaught_exception(exc)
  File "C:\Users\LENOVO\AppData\Roaming\Python\Python312\site-packages\rest_framework\views.py", line 480, in raise_uncaught_exception
    raise exc
  File "C:\Users\LENOVO\AppData\Roaming\Python\Python312\site-packages\rest_framework\views.py", line 506, in dispatch
    response = handler(request, *args, **kwargs)
               ^^^^^^^^^^^^^^^^^^^^^^^^^^^^^^^^^
  File "C:\Users\LENOVO\AppData\Roaming\Python\Python312\site-packages\rest_framework\decorators.py", line 50, in handler
    return func(*args, **kwargs)
           ^^^^^^^^^^^^^^^^^^^^^
  File "D:\V_Project\LMS-New\backend\app\views.py", line 7481, in get_nondb_candidate
    ).values('user__username', 'user__password', 'dtm_upload').order_by('-id')  # Order by id in descending order
      ^^^^^^^^^^^^^^^^^^^^^^^^^^^^^^^^^^^^^^^^^^^^^^^^^^^^^^^^
  File "C:\Users\LENOVO\AppData\Roaming\Python\Python312\site-packages\django\db\models\query.py", line 1360, in values
    clone = self._values(*fields, **expressions)
            ^^^^^^^^^^^^^^^^^^^^^^^^^^^^^^^^^^^^
  File "C:\Users\LENOVO\AppData\Roaming\Python\Python312\site-packages\django\db\models\query.py", line 1355, in _values
    clone.query.set_values(fields)
  File "C:\Users\LENOVO\AppData\Roaming\Python\Python312\site-packages\django\db\models\sql\query.py", line 2473, in set_values
    self.names_to_path(f.split(LOOKUP_SEP), self.model._meta)
  File "C:\Users\LENOVO\AppData\Roaming\Python\Python312\site-packages\django\db\models\sql\query.py", line 1772, in names_to_path
    raise FieldError(
django.core.exceptions.FieldError: Cannot resolve keyword 'user' into field. Choices are: college_id, college_id_id, dtm_upload, email_id, id, password, role, user_name
ERROR 2024-08-24 18:33:30,791 basehttp "GET /api/nondb-candidates/ HTTP/1.1" 500 121534
ERROR 2024-08-24 19:44:03,489 log Internal Server Error: /api/schedule-with-tests/2024-08-24/105/
ERROR 2024-08-24 19:44:03,995 basehttp "GET /api/schedule-with-tests/2024-08-24/105/ HTTP/1.1" 500 59
ERROR 2024-08-24 19:46:31,947 views Catch Key...: question_data_code_3
ERROR 2024-08-24 19:46:32,956 views -----Data From Cache----
ERROR 2024-08-24 19:46:35,809 views -----Data From Database----
ERROR 2024-08-25 16:15:05,697 log Internal Server Error: /api/Candidate/import_excel/
Traceback (most recent call last):
  File "C:\Users\LENOVO\AppData\Roaming\Python\Python312\site-packages\pandas\core\indexes\base.py", line 3805, in get_loc
    return self._engine.get_loc(casted_key)
           ^^^^^^^^^^^^^^^^^^^^^^^^^^^^^^^^
  File "index.pyx", line 167, in pandas._libs.index.IndexEngine.get_loc
  File "index.pyx", line 196, in pandas._libs.index.IndexEngine.get_loc
  File "pandas\\_libs\\hashtable_class_helper.pxi", line 7081, in pandas._libs.hashtable.PyObjectHashTable.get_item
  File "pandas\\_libs\\hashtable_class_helper.pxi", line 7089, in pandas._libs.hashtable.PyObjectHashTable.get_item
KeyError: 'department_id'

The above exception was the direct cause of the following exception:

Traceback (most recent call last):
  File "C:\Users\LENOVO\AppData\Roaming\Python\Python312\site-packages\django\core\handlers\exception.py", line 55, in inner
    response = get_response(request)
               ^^^^^^^^^^^^^^^^^^^^^
  File "C:\Users\LENOVO\AppData\Roaming\Python\Python312\site-packages\django\core\handlers\base.py", line 197, in _get_response
    response = wrapped_callback(request, *callback_args, **callback_kwargs)
               ^^^^^^^^^^^^^^^^^^^^^^^^^^^^^^^^^^^^^^^^^^^^^^^^^^^^^^^^^^^^
  File "C:\Users\LENOVO\AppData\Roaming\Python\Python312\site-packages\django\views\decorators\csrf.py", line 65, in _view_wrapper
    return view_func(request, *args, **kwargs)
           ^^^^^^^^^^^^^^^^^^^^^^^^^^^^^^^^^^^
  File "C:\Users\LENOVO\AppData\Roaming\Python\Python312\site-packages\django\views\generic\base.py", line 104, in view
    return self.dispatch(request, *args, **kwargs)
           ^^^^^^^^^^^^^^^^^^^^^^^^^^^^^^^^^^^^^^^
  File "C:\Users\LENOVO\AppData\Roaming\Python\Python312\site-packages\rest_framework\views.py", line 509, in dispatch
    response = self.handle_exception(exc)
               ^^^^^^^^^^^^^^^^^^^^^^^^^^
  File "C:\Users\LENOVO\AppData\Roaming\Python\Python312\site-packages\rest_framework\views.py", line 469, in handle_exception
    self.raise_uncaught_exception(exc)
  File "C:\Users\LENOVO\AppData\Roaming\Python\Python312\site-packages\rest_framework\views.py", line 480, in raise_uncaught_exception
    raise exc
  File "C:\Users\LENOVO\AppData\Roaming\Python\Python312\site-packages\rest_framework\views.py", line 506, in dispatch
    response = handler(request, *args, **kwargs)
               ^^^^^^^^^^^^^^^^^^^^^^^^^^^^^^^^^
  File "D:\V_Project\LMS-New\backend\app\views.py", line 2152, in post
    df['department_id'] = df['department_id'].apply(get_department_id)
                          ~~^^^^^^^^^^^^^^^^^
  File "C:\Users\LENOVO\AppData\Roaming\Python\Python312\site-packages\pandas\core\frame.py", line 4090, in __getitem__
    indexer = self.columns.get_loc(key)
              ^^^^^^^^^^^^^^^^^^^^^^^^^
  File "C:\Users\LENOVO\AppData\Roaming\Python\Python312\site-packages\pandas\core\indexes\base.py", line 3812, in get_loc
    raise KeyError(key) from err
KeyError: 'department_id'
ERROR 2024-08-25 16:15:06,010 basehttp "POST /api/Candidate/import_excel/ HTTP/1.1" 500 113473
